Workbook
Name açucar: 'COMPOSIÇÃO NUTRICIONAL'!$C$4:$C$32
Name Alimentos: #REF!
Name alimentos: 'COMPOSIÇÃO NUTRICIONAL'!$C$4:$C$569
Name AlimentosTabela: #REF!
Name AntropometriaPeso: [1]Antropometria!$H$8
Name arrozmassa: 'COMPOSIÇÃO NUTRICIONAL'!$C$493:$C$497
Name barras: 'COMPOSIÇÃO NUTRICIONAL'!$C$451:$C$463
Name bebidas: 'COMPOSIÇÃO NUTRICIONAL'!$C$40:$C$49
Name Cacau: 'COMPOSIÇÃO NUTRICIONAL'!$C$552:$C$569
Name Carnepeixe: 'COMPOSIÇÃO NUTRICIONAL'!$C$488:$C$492
Name cereais: 'COMPOSIÇÃO NUTRICIONAL'!$C$50:$C$180
Name fruta: 'COMPOSIÇÃO NUTRICIONAL'!$C$181:$C$241
Name frutossecos: 'COMPOSIÇÃO NUTRICIONAL'!$C$242:$C$255
Name gelados: 'COMPOSIÇÃO NUTRICIONAL'!$C$256:$C$257
Name gelatina: 'COMPOSIÇÃO NUTRICIONAL'!$C$435:$C$439
Name gordura: 'COMPOSIÇÃO NUTRICIONAL'!$C$33:$C$39
Name leguminosas: 'COMPOSIÇÃO NUTRICIONAL'!$C$508:$C$518
Name LeiteIogurte: 'COMPOSIÇÃO NUTRICIONAL'!$C$258:$C$393
Name manteiga: 'COMPOSIÇÃO NUTRICIONAL'!$C$464:$C$487
Name ovo: 'COMPOSIÇÃO NUTRICIONAL'!$C$432:$C$434
Name pão: 'COMPOSIÇÃO NUTRICIONAL'!$C$120:$C$140
Name porçãofruta: 'COMPOSIÇÃO NUTRICIONAL'!$C$507
Name Queijofiambre: 'COMPOSIÇÃO NUTRICIONAL'!$C$396:$C$431
Name sementes: 'COMPOSIÇÃO NUTRICIONAL'!$C$447:$C$450
Name sopas: 'COMPOSIÇÃO NUTRICIONAL'!$C$519:$C$528

Sheet FICHA CLIENTE
C3: CONSULTA DE NUTRIÇÃO - FICHA DE CLIENTE
C4: NOME
C6: DATA NASCIMENTO
A9: PROFISSÃO
A10: CONTACTO TELEFÓNICO
A11: E-MAIL
A12: MOTIVO DA CONSULTA
A13: ALERGIAS/INTOLERÂNCIAS ALIMENTARES
A14: PATOLOGIAS
A15: MEDICAÇÃO
A18: DATA DA CONSULTA | C18: OBSERVAÇÕES/ ALTERAÇÕES AO PLANO ALIMENTAR IMPLEMENTADO

Sheet ANAMNESE
C2: NOME | D2: EDUARDA CARVALHO | I2: OBSERVAÇÕES
C3: DATA NASCIMENTO | D3: 32118 | E3: IDADE | F3: =DATEDIF(D3,TODAY(),"Y") -> 38 | I3: ALIMENTOS QUE NÃO GOSTA, TRANSITO INTESTINAL, CICLO MESNTRUAL,ETC…
C4: SEXO | D4: 1
C5: ETNIA | D5: 0
C6: PROFISSÃO
C7: CONTACTO TELEFÓNICO
C8: E-MAIL
C9: MOTIVO DA CONSULTA
C10: SEGUIMENTO EM NUTRIÇÃO?
C11: ALERGIAS/INTOLERÂNCIAS ALIMENTARES
C12: DESPORTO
C15: HISTÓRIA ALIMENTAR | K15: HISTÓRIA ALIMENTAR | S15: HISTÓRIA ALIMENTAR
C17: 1ªCONSULTA | G17: 44684 | K17: 2ª CONSULTA | S17: 3ª CONSULTA
B18: HORAS/LOCAL | C18: PEQUENO-ALMOÇO | J18: HORAS/LOCAL | K18: PEQUENO-ALMOÇO | R18: HORAS/LOCAL | S18: PEQUENO-ALMOÇO
B25: HORAS/LOCAL | C25: MERENDA DA MANHÃ | J25: HORAS/LOCAL | K25: MERENDA DA MANHÃ | R25: HORAS/LOCAL | S25: MERENDA DA MANHÃ
B31: HORAS/LOCAL | C31: ALMOÇO | J31: HORAS/LOCAL | K31: ALMOÇO | R31: HORAS/LOCAL | S31: ALMOÇO
B41: HORAS/LOCAL | C41: MERENDA DA TARDE | J41: HORAS/LOCAL | K41: MERENDA DA TARDE | R41: HORAS/LOCAL | S41: MERENDA DA TARDE
B48: HORAS/LOCAL | C48: JANTAR | J48: HORAS/LOCAL | K48: JANTAR | R48: HORAS/LOCAL | S48: JANTAR
B58: HORAS/LOCAL | C58: CEIA | J58: HORAS/LOCAL | K58: CEIA | R58: HORAS/LOCAL | S58: CEIA
B64: OBSERVAÇÕES AO ACONSELHAMENTO | J64: OBSERVAÇÕES AO ACONSELHAMENTO | R64: OBSERVAÇÕES AO ACONSELHAMENTO
B65: HIDRATAÇÃO | J65: HIDRATAÇÃO | R65: HIDRATAÇÃO

Sheet ANTROPOMETRIA
B1: AVALIAÇÃO DA COMPOSIÇÃO CORPORAL
B3: Data de Nascimento: | C3: =ANAMNESE!D3 -> 32118 | H3: Classificação de IMC (Segundo OMS)
B4: Idade: | C4: =DATEDIF(C3,TODAY(),"Y") -> 38 | H4: Baixo Peso | I4: <18,5
H5: Normoponderal | I5: 19 - 24,5
H6: Excesso de Peso | I6: 25-30
C7: 1ª CONSULTA | H7: Obesidade | I7: >30
B8: Avaliação Antropométrica
B9: Peso (kg) | H9: Classificação IMC- Percentis pediatria
B10: Altura (cm) | H10: Baixo Peso | I10: <1 sd - 3rd
B11: Altura (m) | C11: =C10/100 -> 0 | H11: Normoponderal | I11: 3rd e 15th/ 15th e 25th / 25th e 50th | J11: 50th e 75th /75th e 85th
B12: IMC | C12: =C9/(C11*C11) -> #DIV/0! | H12: Excesso de Peso | I12: 85th - 95th | J12: 95th e 97th
B13: Perímetros - SOMA | C13: =SUM(C14:C18) -> 0 | H13: Obesidade | I13: 97th e 99th | J13: >= 99th
B14: Perímetro da Cintura (cm)
B15: Perímetro do Braço (cm)
B16: Perímetro da Anca (cm) | H16: Classificação IMC Lipschitz Idosos
B17: Perímetro da Coxa (cm) | H17: Baixo Peso | I17: <22
B18: Perímetro Geminal (cm) | H18: Normoponderal | I18: 22 - 27
B19: Pregas | H19: Excesso de Peso / Obesidade | I19: >27
B20: Prega Tricipital (mm)
B21: Prega Subescapular (mm)
B22: Prega Bicipital (mm)
B23: Prega Iliocristal (mm) | H23: PESO IDEAL MULHERES: | I23: =(C10-100-((C10-150)/2)+((C4-20)/4)) -> -20.5
B24: Prega Supraespinal (mm) | H24: PESO IDEAL HOMENS | I24: =(C10-100-((C10-150)/4)+((C4-20)/4)) -> -58
B25: Prega Abdominal (mm) | J25: Se Idade >45
B26: Prega Geminal (mm) | H26: PESO REFERÊNCIA MULHERES | I26: =(I27) - (0.05*I27) -> -90.155 | J26: =(J27) - (0.05*J27) -> -88.825
B27: Prega Crural (mm) | H27: PESO REFERÊNCIA HOMENS | I27: =((50+(0.75*(C10-150))+(0.8*(C10-100+C4/2)/2))) -> -94.9 | J27: =((50+(0.75*(C10-150))+(0.8*(C10-100+45/2)/2))) -> -93.5
B28: Prega Peitoral (mm)
B29: Soma das Pregas | C29: =SUM(C20:C28) -> 0 | H29: RECOMENDAÇÕES | I29: MULHERES | J29: HOMENS
A30: BIOIMPEDÂNCIA | B30: %MASSA GORDA | H30: % ÁGUA CORPORAL | I30: 45-60% | J30: 50-65%
B31: KG MASSA MAGRA | H31: GORDURA VISCERAL | I31: 1-12 SAUDÁVEL
B32: % Água Corporal | H32: MASSA GORDA | I32: 20-30% | J32: 8-20 %
B33: Gordura Visceral
A34: ANTROPOMETRIA | B34: %MASSA GORDA
B35: KG MASSA MUSCULAR
H36: Valores de Referência %MG- Não Atletas
H37: HOMENS | I37: Não recomendado | J37: Limite Inferior | K37: Médio | L37: Limite Superior | M37: Obesidade
H38: 18-40 Anos | I38: <8 | J38: 8 | K38: 13 | L38: 22 | M38: >22
H39: 40-60 Anos | I39: <10 | J39: 10 | K39: 18 | L39: 25 | M39: >25
B40: Adultos | H40: >60 Anos | I40: <10 | J40: 10 | K40: 16 | L40: 23 | M40: >23
B41: %Massa Gorda | H41: MULHERES | I41: Não recomendado | J41: Limite Inferior | K41: Médio | L41: Limite Superior | M41: Obesidade
...

Sheet Fórmulas 
C2: Necessidades Energéticas
C4: Jovens 3-18Anos
C5: Schofield 3-10 Rapaz | D5: (19.59 x Peso) + (1,033 x Altura (cm)) + 414.9
C6: Schofield 3- 10 Rapariga | D6: (16.8 x Peso) + (1,618 x Altura (cm)) + 371.3
C7: Schofield 10-18 Rapaz | D7: (16.25 x Peso) + (1,373 x Altura (cm)) + 515.5
C8: Schofield 10-18 Rapariga | D8: (8.37 x Peso) + (4,65 x Altura (cm)) + 200
C9: FAO 3-10 Rapaz | D9: (22,7 x Peso) + 495
C10: FAO 3-10 Rapariga | D10: (22,5 x Peso) + 499
C11: FAO Rapaz 10-18 Anos | D11: 17,5*Peso +651
C12: FAO Rapariga 10-18 Anos | D12: 12,2*Peso + 746
C13: Jovens Obesidade 3-18 Anos
C14: Lazzer Rapaz | D14: ((892,68-(Idade*115,93)+(Peso*54,96)+((Altura (m))*1816,23)+1484,5))*0,2388458966275
C15: Lazzer Rapariga | D15: ((0*892,68)-(Idade*115,93)+(Peso*54,96)+(('Altura (m))*1816,23)+1484,5)*0,2388458966275
C17: Adultos
C18: FAO 18-29 Anos Homens | D18: 15.4Peso - 27H + 717)
C19: FAO 18-29 Anos Mulheres | D19: 13.3Peso + 334H + 35)
C20: FAO 30-65 Anos Homens | D20: 11.3Peso + 16H + 901
C21: FAO 30-65 Anos Mulheres | D21: 8.7Peso - 25H + 865)
C23: Cuningham, et al. | D23: 𝐺𝐸𝑅 = 21,6 × 𝑀𝐿𝐺 + 370
C24: Tem-haaf, et al. | D24: 11,936 * weight(kg)+ 587,728 *height(m)- { 8,129 * age(y)+ 191,027* sex(M~1,F~0) + 29,279
C25: Tem-haaf, et al. | D25: 22,771 *FFM + 484,264
C26: Ad Mifflin-St.Jeor, et al. | D26: 𝐺𝐸𝑅 = 19,7 × 𝑀𝐿𝐺 + 413
C28: Composição Corporal
C29: %Massa Gorda
C30: Evans, et.al (M) | D30: %BF= 8.997 6+ 0.24658*(3SKF) – 6.343*(gender) – 1.998*(race), considerando SKF: ABDOMINAL ; Crual ; TRICIPITAL; Sexo: 0F; 1M e Raça: 0 White e 1 Black
C31: Whiters, et.al | D31: BD = 1.0988 − (0.0004 ∗Σ[T, Sb, B, Sp, Ab, crural, geminal])
C32: Carter, et.al
C33: Reilly, et.al (Futebol H) | D33: BF% = 5.174 + (0.124 ∗ Crural) + (0.147 ∗ Ab) + (0.196 ∗ Tricipital) + (0.13 ∗ Geminal)
C34: Jackson homens atletas | D34: ((4,95/d)-4,50)*100. d= 1,112-0,00043499*(soma 7 pregas)+0,00000055*((soma)*(soma))-0,00028826*i
C35: jackson mulheres atletas | D35: ((5,01/d)-4,57)*100. d= 1,096095-0,0006952*(soma subescapular;abdominal;iliocristal;crural))+0,0000011*((soma)*(soma))-0,0000714*i
C37: Mulheres, Não atletas
C38: Peterson, et.al | D38: %BFnew = 22.18945 + (age 0.06368) + (BMI 0.60404)- (height 0.14520) + (sum4 0.30919)- (sum4(2) 0.00099562) [SUM4: tricipital;SB; SP; GEMINAL]
C39: Jackson, et. al | D39: ((5,01/D)-4,57)*100. D=1,089733-0,0009245*(SOMA TRICIPITAL,ABDOMINAL,ILIOCRISTAL)+0,0000025*((SOMA)*(SOMA))-0,0000979*I | E39: %=((4,95/Densidade)-4,50)*100 | F39: x=sum of triceps, chest, and subscapular skinfolds (in mm) for men, and the sum of triceps, suprailium, and abdominal skinfolds for women, and y =age in years
C40: Deurenberg, et al | D40: BF-=1,20*imc +0,23 *i -5,4
C41: Sun et. al | D41: 22,18945 + (i*0,06368) + imc*0,60404-A(cm) *0,14520+ (sum4pregas)*0,30919-((sum4p)*(sum4p))*,00099562. Pregas: tricipital;subescapular;iliocristal;crural
C42: Homens, Não atletas
C43: Peterson, et. al | D43: %BFnew = 20.94878 + (age 0.1166)- (height 0.11666) + (sum4 0.42696)- (sum4 (ao quadrado) *0.00159)
C44: Jackson, et.al | D44: 1.1125025-0.0013125(tricipital+subescapular+peitoral) + 0.0000055((tricipital;subescapular;peitoral)2 ) – 0.0002440(I) | E44: %=((4,95/Densidade)-4,50)*100 | F44: x=sum of triceps, chest, and subscapular skinfolds (in mm) for men, and the sum of triceps, suprailium, and abdominal skinfolds for women, and y =age in years
C45: Deurenberg, et.al | D45: BF-=1,20*imc-10,8*s +0,23 *i -5,4
C46: Durnin & Womersley, et. al
...

Sheet RESULTADOS
C2: AVALIAÇÃO ANTROPOMÉTRICA
C3: Eduarda
C5: 44864
C7: PESO (Kg) | D7: =ANTROPOMETRIA!C9 -> 0 | E7: =ANTROPOMETRIA!D9 -> 0
C8: ALTURA (m) | D8: =ANTROPOMETRIA!C10/100 -> 0 | E8: =ANTROPOMETRIA!D10/100 -> 0
C9: IMC | D9: =ANTROPOMETRIA!C12 -> #DIV/0! | E9: =ANTROPOMETRIA!D12 -> 0
C10: Perímetro da Cintura (cm) | D10: =ANTROPOMETRIA!C14 -> 0 | E10: =ANTROPOMETRIA!D14 -> 0
C11: Perímetro do Braço (cm) | D11: =ANTROPOMETRIA!C15 -> 0 | E11: =ANTROPOMETRIA!D15 -> 0
C12: Perímetro da Anca (cm) | D12: =ANTROPOMETRIA!C16 -> 0 | E12: =ANTROPOMETRIA!D16 -> 0
C13: Perímetro da Coxa (cm) | D13: =ANTROPOMETRIA!C17 -> 0 | E13: =ANTROPOMETRIA!D17 -> 0
C14: Perímetro Geminal (cm) | D14: =ANTROPOMETRIA!C18 -> 0 | E14: =ANTROPOMETRIA!D18 -> 0
C15: SOMA DOS PERÍMETROS | D15: =ANTROPOMETRIA!C13 -> 0 | E15: =ANTROPOMETRIA!D13 -> 0
C16: Prega Tricipital (mm) | D16: =ANTROPOMETRIA!C20 -> 0 | E16: =ANTROPOMETRIA!D20 -> 0
C17: Prega Subescapular (mm) | D17: =ANTROPOMETRIA!C21 -> 0 | E17: =ANTROPOMETRIA!D21 -> 0
C18: Prega Bicipital (mm) | D18: =ANTROPOMETRIA!C22 -> 0 | E18: =ANTROPOMETRIA!D22 -> 0
C19: Prega Iliocristal (mm) | D19: =ANTROPOMETRIA!C23 -> 0 | E19: =ANTROPOMETRIA!D23 -> 0
C20: Prega Supraespinal (mm) | D20: =ANTROPOMETRIA!C24 -> 0 | E20: =ANTROPOMETRIA!D24 -> 0
C21: Prega Abdominal (mm) | D21: =ANTROPOMETRIA!C25 -> 0 | E21: =ANTROPOMETRIA!D25 -> 0
C22: Prega Geminal (mm) | D22: =ANTROPOMETRIA!C26 -> 0 | E22: =ANTROPOMETRIA!D26 -> 0
C23: Prega Crural (mm) | D23: =ANTROPOMETRIA!C27 -> 0 | E23: =ANTROPOMETRIA!D27 -> 0
C24: SOMA DAS PREGAS CUTÂNEAS | D24: =ANTROPOMETRIA!C28 -> 0 | E24: =ANTROPOMETRIA!D28 -> 0
C25: BIOIMPEDÂNCIA
C26: % MASSA GORDA | D26: =ANTROPOMETRIA!C30 -> 0 | E26: =ANTROPOMETRIA!D30 -> 0
C27: Kg MASSA MAGRA | D27: =ANTROPOMETRIA!C31 -> 0 | E27: =ANTROPOMETRIA!D31 -> 0
C28: % ÁGUA CORPORAL | D28: =ANTROPOMETRIA!C32 -> 0 | E28: =ANTROPOMETRIA!D32 -> 0
C29: NÍVEL GORDURA VISCERAL | D29: =ANTROPOMETRIA!C33 -> 0 | E29: =ANTROPOMETRIA!D33 -> 0
C30: ANTROPOMETRIA
C31: %MASSA GORDA | D31: =ANTROPOMETRIA!C34 -> 0 | E31: =ANTROPOMETRIA!D34 -> 0
C32: KG MASSA MUSCULAR | D32: =ANTROPOMETRIA!C35 -> 0 | E32: =ANTROPOMETRIA!D35 -> 0

Sheet NECESSIDADES ENERGÉTICAS
B2: Gasto Energético Basal
B5: Jovens 3-18Anos
B6: Schofield 3-10 Rapaz | C6: =(19.59*ANTROPOMETRIA!C9)+(1.033*ANTROPOMETRIA!C10)+414.9 -> 414.9
B7: Schofield 3- 10 Rapariga | C7: =(16.8*ANTROPOMETRIA!C9)+(1.618*ANTROPOMETRIA!C10)+371.3 -> 371.3
B8: Schofield 10-18 Rapaz | C8: =(16.25*ANTROPOMETRIA!C9)+(1.373*ANTROPOMETRIA!C10)+515.5 -> 515.5
B9: Schofield 10-18 Rapariga | C9: =(8.37*ANTROPOMETRIA!C9)+(4.65*ANTROPOMETRIA!C10)+200 -> 200
B10: FAO 3-10 Rapaz | C10: =(22.7*ANTROPOMETRIA!C9)+495 -> 495
B11: FAO 3-10 Rapariga | C11: =(22.5*ANTROPOMETRIA!C9)+499 -> 499
B12: FAO Rapaz 10-18 Anos | C12: =(17.5*ANTROPOMETRIA!C9) + 746 -> 746
B13: FAO Rapariga 10-18 Anos | C13: =(12.2*ANTROPOMETRIA!C9) +217 -> 217
B14: NE (Kcal)
B16: Jovens Obesidade 3-18Anos
B17: Lazzer Rapaz | C17: =((892.68-(ANTROPOMETRIA!C4*115.93)+(ANTROPOMETRIA!C9*54.96)+((ANTROPOMETRIA!C11)*1816.23)+1484.5))*0.2388458966275 -> -484.41769
B18: Lazzer Rapariga | C18: =((0*892.68)-(ANTROPOMETRIA!C4*115.93)+(ANTROPOMETRIA!C9*54.96)+((ANTROPOMETRIA!C11)*1816.23)+1484.5)*0.2388458966275 -> -697.63065
B19: NE (Kcal)
B21: Adultos
B22: Harris Benedict Homens | C22: =66.5+(13.75*ANTROPOMETRIA!C9)+(5*ANTROPOMETRIA!C10)-(6.78*ANTROPOMETRIA!C4) -> -191.14
B23: Harris Benedict Mulheres | C23: =655.0955+(1.8496*ANTROPOMETRIA!C10)+(9.5634*ANTROPOMETRIA!C9)-(4.6756*ANTROPOMETRIA!C4) -> 477.4227
B25: FAO 18-29 Anos Homens | C25: =(15.4*ANTROPOMETRIA!C9) -(27*(ANTROPOMETRIA!C10/100))+717 -> 717
B26: FAO 18-29 Anos Mulheres | C26: =(13.3*ANTROPOMETRIA!C9)+(334*(ANTROPOMETRIA!C10/100))+35 -> 35
B27: FAO 30-65 Anos Homens | C27: =(11.3*ANTROPOMETRIA!C9)+(16*(ANTROPOMETRIA!C10/100))+901 -> 901
B28: FAO 30-65 Anos Mulheres | C28: =(8.7*ANTROPOMETRIA!C9)-(25*(ANTROPOMETRIA!C10/100))+865 -> 865
B30: Cuningham, et al. | C30: =(21.6*(ANTROPOMETRIA!C9 - ANTROPOMETRIA!C36) )+ 370 -> 370
B32: Tem-haaf, et al. | C32: =(11.936*ANTROPOMETRIA!C9 )+ (587.728*ANTROPOMETRIA!C11) - (8.129*ANTROPOMETRIA!C4) + (191.027*ANAMNESE!D4) + 29.279 -> -88.596
B33: Tem-haaf, et al. | C33: =(22.771*(ANTROPOMETRIA!C9-ANTROPOMETRIA!C38))+ 484.264 -> 484.264
B35: Ad Mifflin-St.Jeor, et al. | C35: =(19.7*(ANTROPOMETRIA!C9-ANTROPOMETRIA!C38))+413 -> 413
B37: NE (Kcal)
B40: Gasto energético Total
B41: GET = NE X FA
C44: Objetivo do Plano
B45: GET =
B48: Fatores de Atividade
B49: PAL Adultos (FAO) | D49: PAL Crianças | E49: Leve | F49: Moderada | G49: Intensa
B50: <1,40 : Muito sedentário | D50: 1-5Anos | E50: 1.45 | F50: 1.6 | G50: -
B51: 1,40- 1,69 : Sedentário | D51: 6 - 13 Anos (H) | E51: 1.55 | F51: 1.75 | G51: 1.95
B52: 1,70- 1,99 : Moderada | D52: 6-13 Anos (M) | E52: 1.5 | F52: 1.7 | G52: 1.9
B53: 2- 2,40 : Vigorosa | D53: 14-18Anos (H) | E53: 1.6 | F53: 1.8 | G53: 2.05
B54: >2,40: Extrema | D54: 14-18 Anos (M) | E54: 1.45 | F54: 1.65 | G54: 1.85
A56: PPT BWIZER | B56: PAL ADULTOS
B57: 1,2 : Sedentário / Pouco ou nenhum exercício
...

Sheet DISTRIBUIÇÃO MACROS
B3: Objetivo do Plano (Kcal): | C3: ='NECESSIDADES ENERGÉTICAS'!C45 -> 0
B5: Distribuição de Macronutrientes | C5: % VET | D5: Kcal | E5: g | F5: g/kg
B6: Proteína | C6: 15 | D6: =(C6/100)*'NECESSIDADES ENERGÉTICAS'!C45 -> 0 | E6: =(D6/4) -> 0 | F6: =E6/ANTROPOMETRIA!C9 -> #DIV/0!
B7: Hidratos de Carbono | C7: 55 | D7: =(C7/100)*'NECESSIDADES ENERGÉTICAS'!C45 -> 0 | E7: =D7/4 -> 0 | F7: =E7/ANTROPOMETRIA!C9 -> #DIV/0!
B8: Lípidos | C8: 30 | D8: =(C8/100)*'NECESSIDADES ENERGÉTICAS'!C45 -> 0 | E8: =D8/9 -> 0 | F8: =E8/ANTROPOMETRIA!C9 -> #DIV/0!
C9: =SUM(C6:C8) -> 100
D11: RECOMENDAÇÕES
B12: DRI JOVENS
A13: HC | B13: 45-65% VET
B14: 3-8 g/Kg
A15: LIP | B15: 25-30%VET
A16: PRT | B16: 1,2-1,8 g/Kg
A19: HC | B19: – < 1 hora média diária de treino – ingestão hidratos carbono de 3 -5g/kg – 1 a 2 horas médias diárias de treino – ingestão hidratos carbono de 5-7g/kg – 2 a 3 horas médias diárias de treino – ingestão hidratos carbono de 6 -10g/kg – 4 a 5 horas médias diárias de treino – ingestão hidratos carbono de 8 -12g/kg
A23: DRI
A24: PT | B24: 0,6 -2,2g/kg/dia
A25: HC | B25: 3-5G/Lg/dia
A26: LP | B26: 05-1,5g/kg/dia
A28: 20g PT, a cada 3horas pós exercício para potenciar os ganhos de massa muscular (0,25 - 0,3g/kg/dia)

Sheet CÁLCULOS PLANO ALIMENTAR
C1: Objetivo | D1: Atual | E1: Diferença
B2: Kcal | C2: ='DISTRIBUIÇÃO MACROS'!C3 -> 0 | D2: =P11+P23+P33+P45+P66+P79+P55 -> #NAME? | E2: =C2-D2 -> #NAME?
B3: PROT (g) | C3: ='DISTRIBUIÇÃO MACROS'!E6 -> 0 | D3: =P12+P24+P34+P46+P67+P80+P56 -> #NAME? | E3: =C3-D3 -> #NAME?
B4: HC (g) | C4: ='DISTRIBUIÇÃO MACROS'!E7 -> 0 | D4: =P13+P25+P35+P47+P68+P81+P57 -> #NAME? | E4: =C4-D4 -> #NAME?
B5: LIP (g) | C5: ='DISTRIBUIÇÃO MACROS'!E8 -> 0 | D5: =P14+P26+P36+P48+P69+P82+P58 -> #NAME? | E5: =C5-D5 -> #NAME?
N8: Valor Nutricional
A9: Pequeno Almoço
A10: Horas | D10: (g/mL) | F10: Kcal | G10: Prot | H10: HC | I10: LP | J10: Observações | N10: Pequeno-Almoço
B11: 1 | C11: Tortita de Arroz | D11: =_xlfn.XLOOKUP(C11,cereais,'COMPOSIÇÃO NUTRICIONAL'!E50:E180,0,0,1)*'CÁLCULOS PLANO ALIMENTAR'!B11 -> #NAME? | F11: =_xlfn.XLOOKUP(C11,cereais,'COMPOSIÇÃO NUTRICIONAL'!F50:F180,0,0,1)*B11 -> #NAME? | G11: =_xlfn.XLOOKUP(C11,cereais,'COMPOSIÇÃO NUTRICIONAL'!G50:G180,0,0,1)*'CÁLCULOS PLANO ALIMENTAR'!B11 -> #NAME? | H11: =_xlfn.XLOOKUP(C11,cereais,'COMPOSIÇÃO NUTRICIONAL'!H50:H180,0,0,1)*'CÁLCULOS PLANO ALIMENTAR'!B11 -> #NAME? | I11: =_xlfn.XLOOKUP(C11,cereais,'COMPOSIÇÃO NUTRICIONAL'!I50:I180,0,0,1)*'CÁLCULOS PLANO ALIMENTAR'!B11 -> #NAME? | N11: Kcal | P11: =F11+F12+F13+F15+F14+F16+F17+F18+F19 -> #NAME?
C12: Fatia de Queijo Flamengo Light fatiado | D12: =_xlfn.XLOOKUP(C12,Queijofiambre,'COMPOSIÇÃO NUTRICIONAL'!E396:E431,0,0,1)*'CÁLCULOS PLANO ALIMENTAR'!B12 -> 0 | F12: =_xlfn.XLOOKUP(C12,Queijofiambre,'COMPOSIÇÃO NUTRICIONAL'!F396:F431,0,0,1)*'CÁLCULOS PLANO ALIMENTAR'!B12 -> 0 | G12: =_xlfn.XLOOKUP(C12,Queijofiambre,'COMPOSIÇÃO NUTRICIONAL'!G396:G431,0,0,1)*'CÁLCULOS PLANO ALIMENTAR'!B12 -> 0 | H12: =_xlfn.XLOOKUP(C12,Queijofiambre,'COMPOSIÇÃO NUTRICIONAL'!H396:H431,0,0,1)*'CÁLCULOS PLANO ALIMENTAR'!B12 -> 0 | I12: =_xlfn.XLOOKUP(C12,Queijofiambre,'COMPOSIÇÃO NUTRICIONAL'!I396:I431,0,0,1)*'CÁLCULOS PLANO ALIMENTAR'!B12 -> 0 | N12: PROT | P12: =G11+G12+G13+G14+G15+G16+G17+G18+G19 -> #NAME?
C13: Colher de Chá de Matinal Extra Light | D13: =_xlfn.XLOOKUP(C13,manteiga,'COMPOSIÇÃO NUTRICIONAL'!E464:E487,0,0,1)*'CÁLCULOS PLANO ALIMENTAR'!B13 -> 0 | F13: =_xlfn.XLOOKUP(C13,manteiga,'COMPOSIÇÃO NUTRICIONAL'!F464:F487,0,0,1)*'CÁLCULOS PLANO ALIMENTAR'!B13 -> 0 | G13: =_xlfn.XLOOKUP(C13,manteiga,'COMPOSIÇÃO NUTRICIONAL'!G464:G487,0,0,1)*'CÁLCULOS PLANO ALIMENTAR'!B13 -> 0 | H13: =_xlfn.XLOOKUP(C13,manteiga,'COMPOSIÇÃO NUTRICIONAL'!H464:H487,0,0,1)*'CÁLCULOS PLANO ALIMENTAR'!B13 -> 0 | I13: =_xlfn.XLOOKUP(C13,manteiga,'COMPOSIÇÃO NUTRICIONAL'!I464:I487,0,0,1)*'CÁLCULOS PLANO ALIMENTAR'!B13 -> 0 | N13: HC | P13: =H11+H12+H13+H14+H15+H17+H16+H18 -> #NAME?
C14: Iogurte Líquido Magro Mimosa, 0%Açúcar | D14: =_xlfn.XLOOKUP(C14,LeiteIogurte,'COMPOSIÇÃO NUTRICIONAL'!E258:E393,0,0,1)*'CÁLCULOS PLANO ALIMENTAR'!B14 -> 0 | F14: =_xlfn.XLOOKUP(C14,LeiteIogurte,'COMPOSIÇÃO NUTRICIONAL'!F258:F393,0,0,1)*'CÁLCULOS PLANO ALIMENTAR'!B14 -> 0 | G14: =_xlfn.XLOOKUP(C14,LeiteIogurte,'COMPOSIÇÃO NUTRICIONAL'!G258:G393,0,0,1)*'CÁLCULOS PLANO ALIMENTAR'!B14 -> 0 | H14: =_xlfn.XLOOKUP(C14,LeiteIogurte,'COMPOSIÇÃO NUTRICIONAL'!H258:H393,0,0,1)*'CÁLCULOS PLANO ALIMENTAR'!B14 -> 0 | I14: =_xlfn.XLOOKUP(C14,LeiteIogurte,'COMPOSIÇÃO NUTRICIONAL'!I258:I393,0,0,1)*'CÁLCULOS PLANO ALIMENTAR'!B14 -> 0 | N14: LIP | P14: =I11+I12+I14+I13+I15+I16+I17+I18 -> #NAME?
C15: Colher de chá de Doce de 4 frutos Casa Mateus, 0%açúcares | D15: =_xlfn.XLOOKUP(C15,açucar,'COMPOSIÇÃO NUTRICIONAL'!E4:E32,0,0,1)*'CÁLCULOS PLANO ALIMENTAR'!B15 -> 0 | F15: =_xlfn.XLOOKUP(C15,açucar,'COMPOSIÇÃO NUTRICIONAL'!F4:F32,0,0,1)*'CÁLCULOS PLANO ALIMENTAR'!B15 -> 0 | G15: =_xlfn.XLOOKUP(C15,açucar,'COMPOSIÇÃO NUTRICIONAL'!G4:G32,0,0,1)*'CÁLCULOS PLANO ALIMENTAR'!B15 -> 0 | H15: =_xlfn.XLOOKUP(C15,açucar,'COMPOSIÇÃO NUTRICIONAL'!H4:H32,0,0,1)*'CÁLCULOS PLANO ALIMENTAR'!B15 -> 0 | I15: =_xlfn.XLOOKUP(C15,açucar,'COMPOSIÇÃO NUTRICIONAL'!I4:I32,0,0,1)*B15 -> 0
C16: 100 gr de Bebida de Cereais Mokambo | D16: =_xlfn.XLOOKUP(C16,Cacau,'COMPOSIÇÃO NUTRICIONAL'!E552:E569,0,0,1)*B16 -> 0 | F16: =_xlfn.XLOOKUP(C16,Cacau,'COMPOSIÇÃO NUTRICIONAL'!F552:F569,0,0,1)*'CÁLCULOS PLANO ALIMENTAR'!B16 -> 0 | G16: =_xlfn.XLOOKUP(C16,Cacau,'COMPOSIÇÃO NUTRICIONAL'!G552:G569,0,0,1)*B16 -> 0 | H16: =_xlfn.XLOOKUP(C16,Cacau,'COMPOSIÇÃO NUTRICIONAL'!H552:H569,0,0,1)*B16 -> 0 | I16: =_xlfn.XLOOKUP(C16,Cacau,'COMPOSIÇÃO NUTRICIONAL'!I552:I569,0,0,1)*B16 -> 0
C17: Porção Fruta | D17: =_xlfn.XLOOKUP(C17,alimentos,'COMPOSIÇÃO NUTRICIONAL'!E4:E569,0,0,1)*B17 -> 0 | F17: =_xlfn.XLOOKUP(C17,alimentos,'COMPOSIÇÃO NUTRICIONAL'!F4:F569,0,0,1)*B17 -> 0 | G17: =_xlfn.XLOOKUP(C17,alimentos,'COMPOSIÇÃO NUTRICIONAL'!G4:G569,0,0,1)*B17 -> 0 | H17: =_xlfn.XLOOKUP(C17,alimentos,'COMPOSIÇÃO NUTRICIONAL'!H4:H569,0,0,1)*'CÁLCULOS PLANO ALIMENTAR'!B17 -> 0 | I17: =_xlfn.XLOOKUP(C17,alimentos,'COMPOSIÇÃO NUTRICIONAL'!I4:I569,0,0,1)*B17 -> 0
C18: Manteiga de Amendoim em pó | D18: =_xlfn.XLOOKUP(C18,alimentos,'COMPOSIÇÃO NUTRICIONAL'!E4:E569,0,0,1)*B18 -> 0 | F18: =_xlfn.XLOOKUP(C18,alimentos,'COMPOSIÇÃO NUTRICIONAL'!F4:F569,0,0,1)*B18 -> 0 | G18: =_xlfn.XLOOKUP(C18,alimentos,'COMPOSIÇÃO NUTRICIONAL'!G4:G569,0,0,1)*B18 -> 0 | H18: =_xlfn.XLOOKUP(C18,alimentos,'COMPOSIÇÃO NUTRICIONAL'!H4:H569,0,0,1)*B18 -> 0 | I18: =_xlfn.XLOOKUP(C18,alimentos,'COMPOSIÇÃO NUTRICIONAL'!I4:I569,0,0,1)*B18 -> 0
A21: Merenda da Manhã | N21: Merenda da Manhã
A22: Horas | B22: Quantidade | D22: (g/mL) | F22: Kcal | G22: Prot | H22: HC | I22: LP | J22: Observações
C23: Bolacha Maria | D23: =_xlfn.XLOOKUP(C23,cereais,'COMPOSIÇÃO NUTRICIONAL'!E50:E180,0,0,1)*'CÁLCULOS PLANO ALIMENTAR'!B23 -> 0 | F23: =_xlfn.XLOOKUP(C23,cereais,'COMPOSIÇÃO NUTRICIONAL'!F50:F180,0,0,1)*B23 -> 0 | G23: =_xlfn.XLOOKUP(C23,cereais,'COMPOSIÇÃO NUTRICIONAL'!G50:G180,0,0,1)*B23 -> 0 | H23: =_xlfn.XLOOKUP(C23,cereais,'COMPOSIÇÃO NUTRICIONAL'!H50:H180,0,0,1)*B23 -> 0 | I23: =_xlfn.XLOOKUP(C23,cereais,'COMPOSIÇÃO NUTRICIONAL'!I50:I180,0,0,1)*B23 -> 0 | N23: Kcal | P23: =F23+F24+F25+F26+F27+F28+F29 -> 0
C24: Queijo Vaca que ri | D24: =_xlfn.XLOOKUP($C$24,Queijofiambre,'COMPOSIÇÃO NUTRICIONAL'!E396:E431,0,0,1)*'CÁLCULOS PLANO ALIMENTAR'!$B$24 -> 0 | F24: =_xlfn.XLOOKUP($C$24,Queijofiambre,'COMPOSIÇÃO NUTRICIONAL'!F396:F431,0,0,1)*'CÁLCULOS PLANO ALIMENTAR'!$B$24 -> 0 | G24: =_xlfn.XLOOKUP($C$24,Queijofiambre,'COMPOSIÇÃO NUTRICIONAL'!G396:G431,0,0,1)*'CÁLCULOS PLANO ALIMENTAR'!$B$24 -> 0 | H24: =_xlfn.XLOOKUP($C$24,Queijofiambre,'COMPOSIÇÃO NUTRICIONAL'!H396:H431,0,0,1)*'CÁLCULOS PLANO ALIMENTAR'!$B$24 -> 0 | I24: =_xlfn.XLOOKUP($C$24,Queijofiambre,'COMPOSIÇÃO NUTRICIONAL'!I396:I431,0,0,1)*'CÁLCULOS PLANO ALIMENTAR'!$B$24 -> 0 | N24: PROT | P24: =G23+G24+G25+G26+G27+G28+G29 -> 0
C25: Colher de Sobremesa de Matinal Magra | D25: =_xlfn.XLOOKUP($C$25,manteiga,'COMPOSIÇÃO NUTRICIONAL'!E464:E487,0,0,1)*'CÁLCULOS PLANO ALIMENTAR'!$B$25 -> 0 | F25: =_xlfn.XLOOKUP($C$25,manteiga,'COMPOSIÇÃO NUTRICIONAL'!F464:F487,0,0,1)*'CÁLCULOS PLANO ALIMENTAR'!$B$25 -> 0 | G25: =_xlfn.XLOOKUP($C$25,manteiga,'COMPOSIÇÃO NUTRICIONAL'!G464:G487,0,0,1)*'CÁLCULOS PLANO ALIMENTAR'!$B$25 -> 0 | H25: =_xlfn.XLOOKUP($C$25,manteiga,'COMPOSIÇÃO NUTRICIONAL'!H464:H487,0,0,1)*'CÁLCULOS PLANO ALIMENTAR'!$B$25 -> 0 | I25: =_xlfn.XLOOKUP($C$25,manteiga,'COMPOSIÇÃO NUTRICIONAL'!I464:I487,0,0,1)*'CÁLCULOS PLANO ALIMENTAR'!$B$25 -> 0 | N25: HC | P25: =H23+H24+H25+H26+H27+H28+H29 -> 0
C26: Copo Pequeno de Leite Meio-Gordo | D26: =_xlfn.XLOOKUP($C$26,LeiteIogurte,'COMPOSIÇÃO NUTRICIONAL'!E258:E393,0,0,1)*'CÁLCULOS PLANO ALIMENTAR'!$B$26 -> 0 | F26: =_xlfn.XLOOKUP($C$26,LeiteIogurte,'COMPOSIÇÃO NUTRICIONAL'!F258:F393,0,0,1)*'CÁLCULOS PLANO ALIMENTAR'!$B$26 -> 0 | G26: =_xlfn.XLOOKUP($C$26,LeiteIogurte,'COMPOSIÇÃO NUTRICIONAL'!G258:G393,0,0,1)*'CÁLCULOS PLANO ALIMENTAR'!$B$26 -> 0 | H26: =_xlfn.XLOOKUP($C$26,LeiteIogurte,'COMPOSIÇÃO NUTRICIONAL'!H258:H393,0,0,1)*'CÁLCULOS PLANO ALIMENTAR'!$B$26 -> 0 | I26: =_xlfn.XLOOKUP($C$26,LeiteIogurte,'COMPOSIÇÃO NUTRICIONAL'!I258:I393,0,0,1)*'CÁLCULOS PLANO ALIMENTAR'!$B$26 -> 0 | N26: LIP | P26: =I23+I24+I25+I26+I28+I27+I29 -> 0
C27: Colher de Chá de Açúcar Branco | D27: =_xlfn.XLOOKUP($C$27,açucar,'COMPOSIÇÃO NUTRICIONAL'!E4:E32,0,0,1)*'CÁLCULOS PLANO ALIMENTAR'!$B$27 -> 0 | F27: =_xlfn.XLOOKUP($C$27,açucar,'COMPOSIÇÃO NUTRICIONAL'!F4:F32,0,0,1)*'CÁLCULOS PLANO ALIMENTAR'!$B$27 -> 0 | G27: =_xlfn.XLOOKUP($C$27,açucar,'COMPOSIÇÃO NUTRICIONAL'!G4:G32,0,0,1)*'CÁLCULOS PLANO ALIMENTAR'!$B$27 -> 0 | H27: =_xlfn.XLOOKUP($C$27,açucar,'COMPOSIÇÃO NUTRICIONAL'!H4:H32,0,0,1)*'CÁLCULOS PLANO ALIMENTAR'!$B$27 -> 0 | I27: =_xlfn.XLOOKUP($C$27,açucar,'COMPOSIÇÃO NUTRICIONAL'!I4:I32,0,0,1)*'CÁLCULOS PLANO ALIMENTAR'!$B$27 -> 0
C28: Porção (10 Unidades) de Morango | D28: =_xlfn.XLOOKUP($C$28,fruta,'COMPOSIÇÃO NUTRICIONAL'!E181:E241,0,0,1)*'CÁLCULOS PLANO ALIMENTAR'!$B$28 -> 0 | F28: =_xlfn.XLOOKUP($C$28,fruta,'COMPOSIÇÃO NUTRICIONAL'!F181:F241,0,0,1)*'CÁLCULOS PLANO ALIMENTAR'!$B$28 -> 0 | G28: =_xlfn.XLOOKUP($C$28,fruta,'COMPOSIÇÃO NUTRICIONAL'!G181:G241,0,0,1)*'CÁLCULOS PLANO ALIMENTAR'!$B$28 -> 0 | H28: =_xlfn.XLOOKUP($C$28,fruta,'COMPOSIÇÃO NUTRICIONAL'!H181:H241,0,0,1)*'CÁLCULOS PLANO ALIMENTAR'!$B$28 -> 0 | I28: =_xlfn.XLOOKUP($C$28,fruta,'COMPOSIÇÃO NUTRICIONAL'!I181:I241,0,0,1)*'CÁLCULOS PLANO ALIMENTAR'!$B$28 -> 0
C29: Ovo Classe M | D29: =_xlfn.XLOOKUP(C29,alimentos,'COMPOSIÇÃO NUTRICIONAL'!E4:E569,0,0,1) -> 58 | F29: =_xlfn.XLOOKUP(C29,alimentos,'COMPOSIÇÃO NUTRICIONAL'!F4:F569,0,0,1)*B29 -> 0 | G29: =_xlfn.XLOOKUP(C29,alimentos,'COMPOSIÇÃO NUTRICIONAL'!G4:G569,0,0,1)*B29 -> 0 | H29: =_xlfn.XLOOKUP(C29,alimentos,'COMPOSIÇÃO NUTRICIONAL'!H4:H569,0,0,1)*B29 -> 0 | I29: =_xlfn.XLOOKUP(C29,alimentos,'COMPOSIÇÃO NUTRICIONAL'!I4:I569,0,0,1)*B29 -> 0
A31: Almoço | N31: Almoço
A32: Horas | B32: Quantidade | D32: (g/mL) | F32: Kcal | G32: Prot | H32: HC | I32: LP | J32: Observações
C33: Tigela Pequena de Sopa de Vegetais | D33: =_xlfn.XLOOKUP(C33,sopas,'COMPOSIÇÃO NUTRICIONAL'!E519:E528,0,0,1)*'CÁLCULOS PLANO ALIMENTAR'!B33 -> 0 | F33: =_xlfn.XLOOKUP(C33,sopas,'COMPOSIÇÃO NUTRICIONAL'!F519:F528,0,0,1)*'CÁLCULOS PLANO ALIMENTAR'!B33 -> 0 | G33: =_xlfn.XLOOKUP(C33,sopas,'COMPOSIÇÃO NUTRICIONAL'!G519:G528,0,0,1)*'CÁLCULOS PLANO ALIMENTAR'!B33 -> 0 | H33: =_xlfn.XLOOKUP(C33,sopas,'COMPOSIÇÃO NUTRICIONAL'!H519:H528,0,0,1)*'CÁLCULOS PLANO ALIMENTAR'!B33 -> 0 | I33: =_xlfn.XLOOKUP(C33,sopas,'COMPOSIÇÃO NUTRICIONAL'!I519:I528,0,0,1)*'CÁLCULOS PLANO ALIMENTAR'!B33 -> 0 | N33: Kcal | P33: =F33+F34+F35+F36+F37+F38+F39+F40 -> 0
C34: 5,5 colheres de Sopa (110g) de arroz ou massa cozinhados OU 1 batata média (120g) | F34: =VLOOKUP(C34,'COMPOSIÇÃO NUTRICIONAL'!C493:G497,4,0)*B34 -> 0 | G34: =VLOOKUP(C34,'COMPOSIÇÃO NUTRICIONAL'!C493:H497,5,0)*B34 -> 0 | H34: =VLOOKUP(C34,'COMPOSIÇÃO NUTRICIONAL'!C493:H497,6,0)*B34 -> 0 | I34: =VLOOKUP(C34,'COMPOSIÇÃO NUTRICIONAL'!C493:I497,7,0)*B34 -> 0 | N34: PROT | P34: =G33+G34+G35+G36+G37+G38+G39+G40 -> 0
C35: 100gr de carne cozinhada OU 120g de pescado cozinhado OU 4 Ovos | F35: =VLOOKUP(C35,'COMPOSIÇÃO NUTRICIONAL'!C488:F492,4,0)*B35 -> 0 | G35: =VLOOKUP(C35,'COMPOSIÇÃO NUTRICIONAL'!C488:G492,5,0)*B35 -> 0 | H35: =VLOOKUP(C35,'COMPOSIÇÃO NUTRICIONAL'!C488:H492,6,0)*B35 -> 0 | I35: =VLOOKUP(C35,'COMPOSIÇÃO NUTRICIONAL'!C488:I492,7,0)*B35 -> 0 | N35: HC | P35: =H33+H34+H35+H36+H37+H38+H39+H40 -> 0
C36: ='COMPOSIÇÃO NUTRICIONAL'!C498 -> 250gr de Hortícolas Cozinhados OU 200gr de legumes em cru | F36: ='COMPOSIÇÃO NUTRICIONAL'!F498*B36 -> 0 | G36: ='COMPOSIÇÃO NUTRICIONAL'!G498*B36 -> 0 | H36: ='COMPOSIÇÃO NUTRICIONAL'!H498*B36 -> 0 | I36: ='COMPOSIÇÃO NUTRICIONAL'!I498*B36 -> 0 | N36: LIP | P36: =I33+I34+I35+I36+I37+I38+I39+I40 -> 0
C37: ='COMPOSIÇÃO NUTRICIONAL'!C499 -> 88gr de leguminosas cozidas | F37: ='COMPOSIÇÃO NUTRICIONAL'!F499*B37 -> 0 | G37: ='COMPOSIÇÃO NUTRICIONAL'!G499*B37 -> 0 | H37: ='COMPOSIÇÃO NUTRICIONAL'!H499*B37 -> 0 | I37: ='COMPOSIÇÃO NUTRICIONAL'!I499*B37 -> 0
C38: ='COMPOSIÇÃO NUTRICIONAL'!C507 -> Porção Fruta | F38: ='COMPOSIÇÃO NUTRICIONAL'!F507*B38 -> 0 | G38: ='COMPOSIÇÃO NUTRICIONAL'!G507*B38 -> 0 | H38: ='COMPOSIÇÃO NUTRICIONAL'!H507*B38 -> 0 | I38: ='COMPOSIÇÃO NUTRICIONAL'!I507*B38 -> 0
C39: 100 gr de Clara de Ovo | D39: =_xlfn.XLOOKUP(C39,alimentos,'COMPOSIÇÃO NUTRICIONAL'!E4:E569,0,0,1)*'CÁLCULOS PLANO ALIMENTAR'!B39 -> 0 | F39: =_xlfn.XLOOKUP(C39,alimentos,'COMPOSIÇÃO NUTRICIONAL'!F4:F569,0,0,1)*'CÁLCULOS PLANO ALIMENTAR'!B39 -> 0 | G39: =_xlfn.XLOOKUP(C39,alimentos,'COMPOSIÇÃO NUTRICIONAL'!G4:G569,0,0,1)*'CÁLCULOS PLANO ALIMENTAR'!B39 -> 0 | H39: =_xlfn.XLOOKUP(C39,alimentos,'COMPOSIÇÃO NUTRICIONAL'!H4:H569,0,0,1)*'CÁLCULOS PLANO ALIMENTAR'!B39 -> 0 | I39: =_xlfn.XLOOKUP(C39,alimentos,'COMPOSIÇÃO NUTRICIONAL'!I4:I569,0,0,1)*'CÁLCULOS PLANO ALIMENTAR'!B39 -> 0
D40: =_xlfn.XLOOKUP(C40,gordura,'COMPOSIÇÃO NUTRICIONAL'!E33:E39,0,0,1)*B40 -> 0 | F40: =_xlfn.XLOOKUP(C40,gordura,'COMPOSIÇÃO NUTRICIONAL'!F33:F39,0,0,1)*B40 -> 0 | G40: =_xlfn.XLOOKUP(C40,gordura,'COMPOSIÇÃO NUTRICIONAL'!G33:G39,0,0,1)*B40 -> 0 | H40: =_xlfn.XLOOKUP(C40,gordura,'COMPOSIÇÃO NUTRICIONAL'!H33:H39,0,0,1)*B40 -> 0 | I40: =_xlfn.XLOOKUP(C40,gordura,'COMPOSIÇÃO NUTRICIONAL'!I33:I39,0,0,1)*B40 -> 0
B41: Bebida: | C41: Água
A43: Merenda da Tarde | N43: Merenda da Tarde
A44: Horas | B44: Quantidade | D44: (g/mL) | F44: Kcal | G44: Prot | H44: HC | I44: LP | J44: Observações
C45: Pacote de Bolacha Água e Sal | D45: =_xlfn.XLOOKUP($C$45,cereais,'COMPOSIÇÃO NUTRICIONAL'!E50:E180,0,0,1)*'CÁLCULOS PLANO ALIMENTAR'!$B$45 -> 0 | F45: =_xlfn.XLOOKUP($C$45,cereais,'COMPOSIÇÃO NUTRICIONAL'!F50:F180,0,0,1)*'CÁLCULOS PLANO ALIMENTAR'!$B$45 -> 0 | G45: =_xlfn.XLOOKUP($C$45,cereais,'COMPOSIÇÃO NUTRICIONAL'!G50:G180,0,0,1)*'CÁLCULOS PLANO ALIMENTAR'!$B$45 -> 0 | H45: =_xlfn.XLOOKUP($C$45,cereais,'COMPOSIÇÃO NUTRICIONAL'!H50:H180,0,0,1)*'CÁLCULOS PLANO ALIMENTAR'!$B$45 -> 0 | I45: =_xlfn.XLOOKUP($C$45,cereais,'COMPOSIÇÃO NUTRICIONAL'!I50:I180,0,0,1)*'CÁLCULOS PLANO ALIMENTAR'!$B$45 -> 0 | N45: Kcal | P45: =F45+F46+F47+F48+F49+F50+F51 -> 0
C46: Queijo Babybel light | D46: =_xlfn.XLOOKUP($C$46,Queijofiambre,'COMPOSIÇÃO NUTRICIONAL'!E396:E431,0,0,1)*'CÁLCULOS PLANO ALIMENTAR'!$B$46 -> 0 | F46: =_xlfn.XLOOKUP($C$46,Queijofiambre,'COMPOSIÇÃO NUTRICIONAL'!F396:F431,0,0,1)*'CÁLCULOS PLANO ALIMENTAR'!$B$46 -> 0 | G46: =_xlfn.XLOOKUP($C$46,Queijofiambre,'COMPOSIÇÃO NUTRICIONAL'!G396:G431,0,0,1)*'CÁLCULOS PLANO ALIMENTAR'!$B$46 -> 0 | H46: =_xlfn.XLOOKUP($C$46,Queijofiambre,'COMPOSIÇÃO NUTRICIONAL'!H396:H431,0,0,1)*'CÁLCULOS PLANO ALIMENTAR'!$B$46 -> 0 | I46: =_xlfn.XLOOKUP($C$46,Queijofiambre,'COMPOSIÇÃO NUTRICIONAL'!I396:I431,0,0,1)*'CÁLCULOS PLANO ALIMENTAR'!$B$46 -> 0 | N46: PROT | P46: =G45+G46+G47+G48+G49+G50+G51 -> 0
...

Sheet PLANO ALIMENTAR
C1: PLANO ALIMENTAR
D3: Eduarda Carvalho
D4: 44854
J7: LISTA DE COMPRAS
A8: PEQUENO-ALMOÇO
A9: Opção 1
A12: Opção 2
A16: MERENDA DA MANHÃ
A17: Opção 1
A20: Opção 2
A24: ALMOÇO e JANTAR
B27: 1/2 prato com hortícolas cozinhados ou frios
A33: Bebida | B33: Água
A34: Sobremesa | B34: 1 porção de fruta
A36: MERENDA DA TARDE
A37: Opção 1
A40: Opção 2
A43: 2ª MERENDA DA TARDE
A47: CEIA
A52: RECOMENDAÇÕES
C74: EDUARDA CARVALHO | Nutricionista
D75: Contacto Telefónico: 910175422
D76: ´@nutri_eduarda | G76: CP: 5084N

Sheet MATERIAIS
L5: 1 PORÇÃO DE FRUTA
L6: A que corresponde?
K8: 140g | M8: Ameixa (3 pequenas) • Ananás (2 fatias sem casca) • Cereja (2 mãos cheias) • Damasco (2 unidades) • framboesas (3 mãos cheias) • Kiwi (2 unidades) • Laranja (1 unidade média) • Maçã (1 unidade média) • Manga, •Nêspera (2 unidades) • Papaia • Pêssego •Romã • Tangerina (2 unidades). 1 banana (120g)
K15: 260g | M15: Morango (8-10 unidades pequenas) • Melancia (1 fatia) • Melão (2 fatias finas) • Mirtilos, Amora.
K19: 350g | M19: Meloa (2 fatias)
M22: Quantas Kcal corresponde 1 porção de fruta
K25: melancia - 38kcal ameixa - 48kcal pêssego - 48kcal dióspiro - 52kcal pêra - 54kcal | M25: meloa - 60kcal mirtilos - 63 kcal figo - 63kcal uvas - 66kcal laranja - 67kcal | O25: ananás- 67kcal damasco- 67kcal framboesas - 69kcal banana - 76kcal melão - 78kcal manga - 82kcal | Q25: kiwi - 84kcal maçã - 87kcal morango - 88kcal cerejas - 94kcal amoras- 111kcal
L36: 1 PORÇÃO DE FRUTOS SECOS - 30g
L37: A que corresponde?
K39: 15 AMÊNDOAS - 20 AVELÃS - 18 CAJUS - 38 PISTÁCIOS - 6 CASTANHAS DO BRASIL - 33 AMENDOINS - 12 NOZES
K54: QUANTIFICAÇÃO ALIMENTAR
K58: HIDRATOS DE CARBONO
J61: 55g
J67: 75g
J73: 110g. Arroz 143
B76: VEGETARIANOS
A77: Equivalente para 125g carne e 150g pescado ---: 250g de tofu OU 125g de seitan OU 100g de soja OU (200g de leguminosas + 55g de arroz integral/massa de leguminosas +1 ovo, e apenas meia porção de fruta de sobremesa)
J79: 165g. Arroz 227
B85: EQUIVALÊNCIAS REFEIÇÕES PRINCIPAIS
A86: 5,5 colheres de Sopa (110g) de arroz ou massa cozinhados (40g em cru) OU 1 batata média (120g) ;3 colheres de sopa (55g) de arroz ou massa cozinhados (20g em cru) OU 1 batata pequena (60g);8 colheres de sopa (165g) de arroz ou massa cozinhados (66g em cru) OU 4 batatas pequenas (180g); 11 colheres de Sopa (220g) de arroz ou massa cozinhados (88g em cru) OU 2 batatas médias (240g) ;16,5 colheres de Sopa (330g) de arroz ou massa cozinhados (129g em cru) OU 3 batatas médias (360g)
K91: PROTEÍNA
A93: 75gr de carne cozinhada (90g em cru) OU 90g de pescado cozinhado (105g em cru) OU 3 Ovos; 100gr de carne cozinhada (120g cru) OU 120g (145g) de pescado cozinhado OU 4 Ovos; 125gr de carne cozinhada (150g em cru) OU 150g de pescado cozinhado (180g em cru) OU 5 Ovos | J93: 75g
A102: PHISIOCLINIC | J102: 100g
A103: Contacto Telefónico: 916294195
A104: ´@_phisioclinic_ | C104: nutricao@phisioclinic.pt
A108: NUTRIÇÃO AURANUA | J108: 189g/240
A109: Contacto Telefónico: 928133743
A110: ´@auranua.com_ | C110: info.auranua@gmail.com
A111: ´@nutri_eduarda
A112: www.auranua.com
J127: 150g

Sheet RECEITAS
E2: 353.591 | F2: 28.5568 | G2: 31.0666 | H2: 12.535
C3: Alimento | D3: Quantidade | E3: Kcal | F3: pt | G3: HC | H3: lp | K3: PAPAS DE AVEIA NO FORNO | W3: PÃO NA AIRFRYER
C4: Ovo Classe M | D4: =_xlfn.XLOOKUP(C4,alimentos,'COMPOSIÇÃO NUTRICIONAL'!E4:E569,0,0,1)*B4 -> 0 | E4: =_xlfn.XLOOKUP(C4,alimentos,'COMPOSIÇÃO NUTRICIONAL'!F4:F569,0,0,1)*B4 -> 0 | F4: =_xlfn.XLOOKUP(C4,alimentos,'COMPOSIÇÃO NUTRICIONAL'!G4:G569,0,0,1)*B4 -> 0 | G4: =_xlfn.XLOOKUP(C4,alimentos,'COMPOSIÇÃO NUTRICIONAL'!H4:H569,0,0,1)*B4 -> 0 | H4: =_xlfn.XLOOKUP(C4,alimentos,'COMPOSIÇÃO NUTRICIONAL'!I4:I569,0,0,1)*B4 -> 0 | K4: Ingredientes: 1 ovo classe M; 1 banana madura; 15g de farinha de aveia; 50g de flocos de aveia; 100 ml (1/2 copo) de leite magro; 1 colher de chá de fermento; canela a gosto Preparação: Misturar todos os ingredientes (com exceção da banana). Colocar num tabuleiro forrado com papel vegetal. Adicionar a banana às rodelas, envolvendo na mistura anterior. Polvilhar com canela e levar ao forno (180ºC) cerca de 25-30 minutos. | W4: 70g de farinha de aveia; 1 colher café de fermento; 150g iogurte skyr natural sólido. Preparação: juntar tudo e temperar com um pouco de sal. Aamassar bem até formar uma bola. Passar farinha em ambos os lados e moldar a gosto. Levar à airfryer a 180º por 15 minutos. Abrir o pão ao meio e deixar mais 5 minutos a cozinhar.
C5: Tortita de Arroz | D5: =_xlfn.XLOOKUP(C5,alimentos,'COMPOSIÇÃO NUTRICIONAL'!E4:E569,0,0,1)*B5 -> 0 | E5: =_xlfn.XLOOKUP(C5,alimentos,'COMPOSIÇÃO NUTRICIONAL'!F4:F569,0,0,1)*B5 -> 0 | F5: =_xlfn.XLOOKUP(C5,alimentos,'COMPOSIÇÃO NUTRICIONAL'!G4:G569,0,0,1)*B5 -> 0 | G5: =_xlfn.XLOOKUP(C5,alimentos,'COMPOSIÇÃO NUTRICIONAL'!H4:H569,0,0,1)*B5 -> 0 | H5: =_xlfn.XLOOKUP(C5,alimentos,'COMPOSIÇÃO NUTRICIONAL'!I4:I569,0,0,1)*B5 -> 0
C6: Porção Fruta | D6: =_xlfn.XLOOKUP(C6,alimentos,'COMPOSIÇÃO NUTRICIONAL'!E4:E569,0,0,1)*B6 -> 0 | E6: =_xlfn.XLOOKUP(C6,alimentos,'COMPOSIÇÃO NUTRICIONAL'!F4:F569,0,0,1)*B6 -> 0 | F6: =_xlfn.XLOOKUP(C6,alimentos,'COMPOSIÇÃO NUTRICIONAL'!G4:G569,0,0,1)*B6 -> 0 | G6: =_xlfn.XLOOKUP(C6,alimentos,'COMPOSIÇÃO NUTRICIONAL'!H4:H569,0,0,1)*B6 -> 0 | H6: =_xlfn.XLOOKUP(C6,alimentos,'COMPOSIÇÃO NUTRICIONAL'!I4:I569,0,0,1)*B6 -> 0
C7: Iogurte soja natural continente equilíbrio | D7: =_xlfn.XLOOKUP(C7,alimentos,'COMPOSIÇÃO NUTRICIONAL'!E4:E569,0,0,1)*B7 -> 0 | E7: =_xlfn.XLOOKUP(C7,alimentos,'COMPOSIÇÃO NUTRICIONAL'!F4:F569,0,0,1)*B7 -> 0 | F7: =_xlfn.XLOOKUP(C7,alimentos,'COMPOSIÇÃO NUTRICIONAL'!G4:G569,0,0,1)*B7 -> 0 | G7: =_xlfn.XLOOKUP(C7,alimentos,'COMPOSIÇÃO NUTRICIONAL'!H4:H569,0,0,1)*B7 -> 0 | H7: =_xlfn.XLOOKUP(C7,alimentos,'COMPOSIÇÃO NUTRICIONAL'!I4:I569,0,0,1)*B7 -> 0
C8: Porção Fruta | D8: =_xlfn.XLOOKUP(C8,alimentos,'COMPOSIÇÃO NUTRICIONAL'!E4:E569,0,0,1)*B8 -> 0 | E8: =_xlfn.XLOOKUP(C8,alimentos,'COMPOSIÇÃO NUTRICIONAL'!F4:F569,0,0,1)*B8 -> 0 | F8: =_xlfn.XLOOKUP(C8,alimentos,'COMPOSIÇÃO NUTRICIONAL'!G4:G569,0,0,1)*B8 -> 0 | G8: =_xlfn.XLOOKUP(C8,alimentos,'COMPOSIÇÃO NUTRICIONAL'!H4:H569,0,0,1)*B8 -> 0 | H8: =_xlfn.XLOOKUP(C8,alimentos,'COMPOSIÇÃO NUTRICIONAL'!I4:I569,0,0,1)*B8 -> 0
C9: Colher de Sopa de Azeite | D9: =_xlfn.XLOOKUP(C9,alimentos,'COMPOSIÇÃO NUTRICIONAL'!E4:E569,0,0,1)*B9 -> 0 | E9: =_xlfn.XLOOKUP(C9,alimentos,'COMPOSIÇÃO NUTRICIONAL'!F4:F569,0,0,1)*B9 -> 0 | F9: =_xlfn.XLOOKUP(C9,alimentos,'COMPOSIÇÃO NUTRICIONAL'!G4:G569,0,0,1)*B9 -> 0 | G9: =_xlfn.XLOOKUP(C9,alimentos,'COMPOSIÇÃO NUTRICIONAL'!H4:H569,0,0,1)*B9 -> 0 | H9: =_xlfn.XLOOKUP(C9,alimentos,'COMPOSIÇÃO NUTRICIONAL'!I4:I569,0,0,1)*B9 -> 0
C10: Iogurte Origem Vegetal Alpro Natural, 0%Açúcar | D10: =_xlfn.XLOOKUP(C10,alimentos,'COMPOSIÇÃO NUTRICIONAL'!E4:E569,0,0,1)*B10 -> 0 | E10: =_xlfn.XLOOKUP(C10,alimentos,'COMPOSIÇÃO NUTRICIONAL'!F4:F569,0,0,1)*B10 -> 0 | F10: =_xlfn.XLOOKUP(C10,alimentos,'COMPOSIÇÃO NUTRICIONAL'!G4:G569,0,0,1)*B10 -> 0 | G10: =_xlfn.XLOOKUP(C10,alimentos,'COMPOSIÇÃO NUTRICIONAL'!H4:H569,0,0,1)*B10 -> 0 | H10: =_xlfn.XLOOKUP(C10,alimentos,'COMPOSIÇÃO NUTRICIONAL'!I4:I569,0,0,1)*B10 -> 0
C11: Receita | D11: Bolachas de Banana | E11: =E4+E5+E6+E8+E7+E9+E10+E13+E14 -> 299.17 | F11: =F4+F5+F6+F7+F8+F9+F10+F13+F14 -> 24.595625 | G11: =G4+G5+G6+G7+G8+G9+G10+G13+G14 -> 29.0285 | H11: =H4+H5+H6+H7+H8+H9+H10+H13+H14 -> 9.288 | K11: PANQUECAS DE BANANA E AVEIA
C12: Porção | D12: 8 | E12: =E11/D12*B12 -> 0 | F12: =F11/D12*B12 -> 0 | G12: =G11/D12*B12 -> 0 | H12: =H11/D12*B12 -> 0 | K12: Ingredientes: Ovo classe M ; 1 colher de sopa de Farinha de Aveia; ½ banana Opcional: Canela Preparação: Começa por triturar, com a ajuda de um garfo, a meia banana. Num recipiente, mistura a banana esmagada, o ovo, a farinha e a canela, até obteres uma mistura homogénea. Numa frigideira antiaderente, adiciona pequenas porções do preparado. Deixa cozer entre 1 a 2 minutos de cada lado. | W12: BAGEL
B13: 0.8 | C13: Whey sabor | E13: =118.2*B13 -> 94.56 | F13: =22.8*B13 -> 18.24 | G13: =1.02*B13 -> 0.816 | H13: =2.55*B13 -> 2.04 | W13: Ingredientes: 35g farinha à escolha; 30g iogurte natural magro; 1 colher de chá de sementes. Preparação: Juntar tudo e moldar em forma de bagel. Untar a massa com as sementes e levar ao forno pré-aquecido, por cerca de 12 minutos.
E14: =E74 -> 204.61 | F14: =F74 -> 6.355625 | G14: =G74 -> 28.2125 | H14: =H74 -> 7.248
C15: Receitas | D15: Quantidade | E15: Kcal | F15: pt | G15: HC | H15: lp
C16: PAPAS DE AVEIA E BANANA NO FORNO - rende 4 porções | D16: 1 porção | E16: 110.21535 | F16: 5.10114 | G16: 15.204595 | H16: 2.80466
C17: PANQUECAS DE BANANA E AVEIA | E17: 189 | F17: 10.7 | G17: 18.23 | H17: 7.72 | K17: PANQUECAS DE IOGURTE E AVEIA
C18: PANQUECAS DE IOGURTE E AVEIA - rende 4 porções | D18: 2 porções | E18: 163.33 | F18: 10.08 | G18: 18.52 | H18: 5.06 | K18: Ingredientes: 1 ovo Classe M - 1 Iogurte sólido de aromas magro - 2 colheres de sopa de flocos de aveia - 2 colheres de sopa de farinha de aveia - Opcional: Canela a gosto Preparação: Deves optar por cozinhá-las numa frigideira antiaderente, para que não necessites mais do que 1 colher de café de azeite na sua confeção!
C19: BOLO DE BANANA E AVEIA- rende 8 fatias | D19: 1 porção | E19: 125.8 | F19: 5.7 | G19: 16.36 | H19: 3.72
C20: CREPES - rende 4 crepes | D20: 2 porções | E20: 146.41 | F20: 10.32 | G20: 11.38 | H20: 6.55
C21: CREPES DE CLARA, IOGURTE E CACAU | D21: 1porção | E21: =96.13*2 -> 192.26 | F21: =7.7*2 -> 15.4 | G21: =11.97*2 -> 23.94 | H21: =1.63*2 -> 3.26 | W21: pão de Batata
C22: PAPAS DE AVEIA, MAÇÃ E CANELA | D22: 1 porção | E22: 285.122 | F22: 11.3116 | G22: 49.3062 | H22: 3.338 | W22: 1 ovo - 30g farinha de trigo - 1 colher de sopa azeite - 100ml leite magro - 1 colher de sopa de sementes - 100g batata cozida -. Preparação_ 10 mintuos na air fryer
C23: PANQUECAS DE CAJU E BANANA | E23: 216.4 | F23: 11.07 | G23: 10.88 | H23: 13.91
C24: SMOTHIE | E24: 432.5214 | F24: 18.91956 | G24: 59.70838 | H24: 11.25964 | K24: BOLO DE BANANA E AVEIA
C25: SMOTHIE | D25: 1/2 porção | E25: =(E24/2) -> 216.2607 | F25: =(F24/2) -> 9.45978 | G25: =(G24/2) -> 29.85419 | H25: =(H24/2) -> 5.62982 | K25: Ingredientes: 2 bananas maduras – 3 ovos – 100g de farinha de aveia – 40g de flocos de aveia – 1colher de chá de fermento – canela a gosto Preparação: Começa por triturar, com ajuda de um garfo, as bananas. Num recipiente, adiciona a farinha os flocos de aveia, os ovos e mexe até obter uma mistura homogénea. De seguida, adiciona as bananas trituradas, o fermento e canela a gosto. Leva ao forno (pré-aquecido a 180ºC), durante 30 minutos. O bolo deve ser dividido em 8 fatias iguais. Para versão de queque, adicionar em 8 formas e levar apenas 17 minutos ao forno.
C26: BOLO DE CENOURA E LARANJA | D26: 1 Fatia | E26: 98.7725 | F26: 5.44375 | G26: 10.97625 | H26: 3.344
C27: PANQUECAS DE CAJU E BANANA - COM CLARA OVO | E27: 228.0364 | F27: 19.11056 | G27: 19.90888 | H27: 7.79264
C28: PANQUECAS BANANA E AVEIA - COM CLARA OVO | E28: 181.4264 | F28: 13.78056 | G28: 26.90888 | H28: 1.60664 | W28: Rice Cake
C29: PANQUECAS DE CENOURA E BANANA - COM CLARA | D29: 2 Panquecas | E29: 373.14 | F29: 20.19 | G29: 59.95 | H29: 5.56 | W29: Rende 15 porções! 500g arroz muito bem cozido;1L de água;pitada de canela;300g queijo creme light; 1 colher de sopa de mel ou agave; Preparação: 1. Cubra o arroz com a água e cozinhe. Adicione a canela para dar sabor.No fim, quase toda a água deverá ter sido absorvida. 2. Com o arroz ainda quente, acrescente o queijo creme e o mel. 3. Misturar bem num tabuleiro plano. Cubrir tudo, embrulhar em pelúcila aderente e deixar no frigorífico durante a noite. 4. Corte em 15 pedaços e embrulha em papel de alumínio individualmente.
C30: MUFFINS CENOURA E BANANA - COM CLARA | D30: 1 | E30: 93.29 | F30: 5.04 | G30: 14.9 | H30: 1.39
C31: BOLACHAS DE BANANA E FLOCOS DE AVEIA + CACAU | D31: 1 | E31: 34.39664 | F31: 1.039056 | G31: 5.738888 | H31: 0.625664
C32: MUFFINS CENOURA E BANANA - COM CLARA | D32: 1 muffin | E32: 124.38107 | F32: 6.7284267 | G32: 19.983147 | H32: 1.8521067
C33: PANQUECAS DE LARANJA | D33: completa | E33: 320 | F33: 24 | G33: 32.8 | H33: 9.44 | K33: CREPES
C34: PANQUECAS DE IOGURTE ALPRO E AVEIA | D34: Receita completa - 7 panquecas | E34: 317.24 | F34: 22.42 | G34: 40.136 | H34: 6.748 | K34: Ingredientes: 2 colheres de sopa de farinha de trigo; 2 ovos; 10 colheres de sopa de leite magro Preparação: Deves proceder à preparação como se fosse uma “panqueca gigante”, adicionando todo o preparado de uma só vez numa frigideira antiaderente por cerca de 1-2minutos de cada lado.
C35: BOLO DA CANECA DE CACAU | D35: 1 UNIDADE | E35: 175.085 | F35: 12.13 | G35: 11.88 | H35: 8.1705
C36: PANQUECAS POLVILHO | E36: 129.2 | F36: 10.96 | G36: 21.99 | H36: 0.02 | W36: Bolacha de Caju
C37: PANQUECA DE MAÇÃ E CANELA | D37: RECEITA COMPLETA | E37: 370.892 | F37: 21.8736 | G37: 50.7712 | H37: 8.048 | W37: 100g flocos de aveia; 100g cajus; 2 colheres de sopa de água; 2 colheres de sopa de mel; levar 20 minutos ao forno.
C38: PANQUECA DE MAÇÃ E CANELA | D38: 1/2 RECEITA | E38: =E37/2 -> 185.446 | F38: =F37/2 -> 10.9368 | G38: =G37/2 -> 25.3856 | H38: =H37/2 -> 4.024
C39: PANQUECAS DE MAÇÃ E CANELA COM 1/2 WHEY, SEM OVO | D39: RECEITA COMPLETA | E39: 343.572 | F39: 25.7336 | G39: 51.2812 | H39: 3.059 | K39: PAPAS DE AVEIA, MAÇÃ E CANELA
C40: PANQUECA MAÇÃ E CLARA OVO | E40: 226.422 | F40: 18.6186 | G40: 33.9712 | H40: 1.381 | K40: Ingredientes: 1 copo de leite (200ml); 30g de flocos de aveia; 1 maçã às rodelas; canela q.b. Preparação: Começa por cozer as rodelas de 1/2 maçã. De seguida, coloca, num recipiente em lume médio, o leite, os flocos de aveia e a maçã. Deves ir mexendo o preparado até obteres a consistência desejada. Passa o preparado para uma taça, adiciona a outra metade da maçã em rodelas e polvilha com canela.
C41: BOLO UNIDADE MAÇÃ DESERT
...

Sheet IMC
A1: BMI-for-age GIRLS
A2: 2 to 19 years (percentiles)
A4: Percentiles (BMI in kg/m2)
A5: Year: Month | B5: Month | C5: L | D5: M | E5: S | F5: <1st | G5: 1st | H5: 3rd | I5: 5th | J5: 15th | K5: 25th | L5: 50th | M5: 75th | N5: 85th | O5: 95th | P5: 97th | Q5: 99th | R5: >99
A6: 2: 0 | B6: 24 | C6: -0.568 | D6: 15.688 | E6: 0.0845 | F6: -1 | G6: 13 | H6: 13.5 | I6: 13.7 | J6: 14.4 | K6: 14.8 | L6: 15.7 | M6: 16.6 | N6: 17.2 | O6: 18.1 | P6: 18.5 | Q6: 19.3 | R6: 9999
A7: 2: 1 | B7: 25 | C7: -0.5684 | D7: 15.659 | E7: 0.08452 | F7: -1 | G7: 13 | H7: 13.4 | I7: 13.7 | J7: 14.4 | K7: 14.8 | L7: 15.7 | M7: 16.6 | N7: 17.1 | O7: 18.1 | P7: 18.5 | Q7: 19.3 | R7: 9999
A8: 2: 2 | B8: 26 | C8: -0.5684 | D8: 15.6308 | E8: 0.08449 | F8: -1 | G8: 13 | H8: 13.4 | I8: 13.7 | J8: 14.4 | K8: 14.8 | L8: 15.6 | M8: 16.6 | N8: 17.1 | O8: 18.1 | P8: 18.5 | Q8: 19.3 | R8: 9999
A9: 2: 3 | B9: 27 | C9: -0.5684 | D9: 15.6037 | E9: 0.08446 | F9: -1 | G9: 13 | H9: 13.4 | I9: 13.7 | J9: 14.3 | K9: 14.8 | L9: 15.6 | M9: 16.5 | N9: 17.1 | O9: 18 | P9: 18.4 | Q9: 19.2 | R9: 9999
A10: 2: 4 | B10: 28 | C10: -0.5684 | D10: 15.5777 | E10: 0.08444 | F10: -1 | G10: 12.9 | H10: 13.4 | I10: 13.6 | J10: 14.3 | K10: 14.7 | L10: 15.6 | M10: 16.5 | N10: 17 | O10: 18 | P10: 18.4 | Q10: 19.2 | R10: 9999
A11: 2: 5 | B11: 29 | C11: -0.5684 | D11: 15.5523 | E11: 0.08443 | F11: -1 | G11: 12.9 | H11: 13.4 | I11: 13.6 | J11: 14.3 | K11: 14.7 | L11: 15.6 | M11: 16.5 | N11: 17 | O11: 18 | P11: 18.4 | Q11: 19.2 | R11: 9999
A12: 2: 6 | B12: 30 | C12: -0.5684 | D12: 15.5276 | E12: 0.08444 | F12: -1 | G12: 12.9 | H12: 13.3 | I12: 13.6 | J12: 14.3 | K12: 14.7 | L12: 15.5 | M12: 16.5 | N12: 17 | O12: 17.9 | P12: 18.3 | Q12: 19.1 | R12: 9999
A13: 2: 7 | B13: 31 | C13: -0.5684 | D13: 15.5034 | E13: 0.08448 | F13: -1 | G13: 12.9 | H13: 13.3 | I13: 13.6 | J13: 14.2 | K13: 14.7 | L13: 15.5 | M13: 16.4 | N13: 17 | O13: 17.9 | P13: 18.3 | Q13: 19.1 | R13: 9999
A14: 2: 8 | B14: 32 | C14: -0.5684 | D14: 15.4798 | E14: 0.08455 | F14: -1 | G14: 12.8 | H14: 13.3 | I14: 13.5 | J14: 14.2 | K14: 14.6 | L14: 15.5 | M14: 16.4 | N14: 16.9 | O14: 17.9 | P14: 18.3 | Q14: 19.1 | R14: 9999
A15: 2: 9 | B15: 33 | C15: -0.5684 | D15: 15.4572 | E15: 0.08467 | F15: -1 | G15: 12.8 | H15: 13.3 | I15: 13.5 | J15: 14.2 | K15: 14.6 | L15: 15.5 | M15: 16.4 | N15: 16.9 | O15: 17.9 | P15: 18.3 | Q15: 19 | R15: 9999
A16: 2:10 | B16: 34 | C16: -0.5684 | D16: 15.4356 | E16: 0.08484 | F16: -1 | G16: 12.8 | H16: 13.2 | I16: 13.5 | J16: 14.2 | K16: 14.6 | L16: 15.4 | M16: 16.4 | N16: 16.9 | O16: 17.9 | P16: 18.2 | Q16: 19 | R16: 9999
A17: 2:11 | B17: 35 | C17: -0.5684 | D17: 15.4155 | E17: 0.08506 | F17: -1 | G17: 12.8 | H17: 13.2 | I17: 13.5 | J17: 14.1 | K17: 14.6 | L17: 15.4 | M17: 16.3 | N17: 16.9 | O17: 17.8 | P17: 18.2 | Q17: 19 | R17: 9999
... A210: 19: 0 | B210: 228 | C210: -0.7496 | D210: 21.4269 | E210: 0.14441 | F210: -1 | G210: 15.879 | H210: 16.734 | I210: 17.22 | J210: 18.593 | K210: 19.504 | L210: 21.427 | M210: 23.707 | N210: 25.113 | O210: 27.833 | P210: 29.03 | Q210: 31.553 | R210: 9999

Sheet PEDIATRIA
A1: Turma | B1: Nº | C1: Nome | D1: Data Medição | E1: Data Nascimento | F1: Meses | G1: Anos e Meses | H1: Peso | I1: Altura | J1: Altura (cm) | K1: PC | L1: PC/alt | M1: IMC | N1: Linha | O1: Coluna | P1: Perc IMC | Q1: Classificação IMC | R1: Linha | S1: Coluna | T1: Perc cint | U1: IMC ideal | V1: Coluna pretendida | W1: Perc IMC ideal | X1: Peso ideal | Y1: Peso a perder | AA1: <1st | AB1: 1st | AC1: 3rd | AD1: 5th | AE1: 15th | AF1: 25th | AG1: 50th | AH1: 75th | AI1: 85th | AJ1: 95th | AK1: 97th | AL1: 99th | AM1: >99
D2: 44717 | E2: 38797 | F2: =DATEDIF(E2,D2,"M") -> 194 | G2: =YEARFRAC(D2,E2) -> 16.205556 | H2: 59 | I2: 1.75 | J2: =I2*100 -> 175 | K2: 70 | L2: =K2/J2 -> 0.4 | M2: =IF(H2>0,IF(I2>0,H2/I2^2,""),"") -> 19.265306 | N2: =MATCH(F2,[2]IMC!B:B,0) -> 176 | O2: =MATCH(M2,INDIRECT("IMC!F" & N2 & ":R" &N2),1) -> 6 | P2: =CONCATENATE(INDEX(IMC!$F$1:$R$5,5,$O2) & " e " & INDEX(IMC!$F$1:$R$5,5,$O2+1)) -> 25th e 50th | R2: =MATCH(F2,[3]PC!A:A,0) -> 82 | S2: =MATCH(K2,INDIRECT("PC!E" & R2 & ":L" &R2),1) -> #REF! | T2: =CONCATENATE(INDEX([3]PC!$E$1:$M$2,1,$S2) & " e " & INDEX([3]PC!$E$1:$M$2,1,$S2+1)) -> #REF! | U2: 17 | V2: =MATCH(U2,INDIRECT("IMC!F" & N2 & ":R" &N2),1) -> 4 | W2: =CONCATENATE(INDEX([3]IMC!$F$1:$R$5,5,$V2) & " e " & INDEX([3]IMC!$F$1:$R$5,5,$V2+1)) -> 5th e 15th | X2: =U2*(I2*I2) -> 52.0625 | Y2: =H2-X2 -> 6.9375 | AA2: =VLOOKUP(F2,[3]IMC!$B$6:$R$210,5,FALSE) -> -1 | AB2: =VLOOKUP(F2,[3]IMC!$B$6:$R$210,6,FALSE) -> 15.651 | AC2: =VLOOKUP(F2,[3]IMC!$B$6:$R$210,7,FALSE) -> 16.424 | AD2: =VLOOKUP(F2,[3]IMC!$B$6:$R$210,8,FALSE) -> 16.866 | AE2: =VLOOKUP(F2,[3]IMC!$B$6:$R$210,9,FALSE) -> 18.123 | AF2: =VLOOKUP(F2,[3]IMC!$B$6:$R$210,10,FALSE) -> 18.966 | AG2: =VLOOKUP(F2,[3]IMC!$B$6:$R$210,11,FALSE) -> 20.767 | AH2: =VLOOKUP(F2,[3]IMC!$B$6:$R$210,12,FALSE) -> 22.951 | AI2: =VLOOKUP(F2,[3]IMC!$B$6:$R$210,13,FALSE) -> 24.326 | AJ2: =VLOOKUP(F2,[3]IMC!$B$6:$R$210,14,FALSE) -> 27.056 | AK2: =VLOOKUP(F2,[3]IMC!$B$6:$R$210,15,FALSE) -> 28.289 | AL2: =VLOOKUP(F2,[3]IMC!$B$6:$R$210,16,FALSE) -> 30.957 | AM2: =VLOOKUP(F2,[3]IMC!$B$6:$R$210,17,FALSE) -> 9999
D3: 44717 | E3: 38797 | F3: =DATEDIF(E3,D3,"M") -> 194 | G3: =YEARFRAC(D3,E3) -> 16.205556 | H3: 59 | I3: 1.75 | J3: =I3*100 -> 175 | L3: =K3/J3 -> 0 | M3: =IF(H3>0,IF(I3>0,H3/I3^2,""),"") -> 19.265306 | N3: =MATCH(F3,[2]IMC!B:B,0) -> 176 | O3: =MATCH(M3,INDIRECT("IMC!F" & N3 & ":R" &N3),1) -> 6 | P3: =CONCATENATE(INDEX(IMC!$F$1:$R$5,5,$O3) & " e " & INDEX(IMC!$F$1:$R$5,5,$O3+1)) -> 25th e 50th | R3: =MATCH(F3,[3]PC!A:A,0) -> 82 | S3: =MATCH(K3,INDIRECT("PC!E" & R3 & ":L" &R3),1) -> #REF! | T3: =CONCATENATE(INDEX([3]PC!$E$1:$M$2,1,$S3) & " e " & INDEX([3]PC!$E$1:$M$2,1,$S3+1)) -> #REF! | W3: =CONCATENATE(INDEX([3]IMC!$F$1:$R$5,5,$V3) & " e " & INDEX([3]IMC!$F$1:$R$5,5,$V3+1)) -> #VALUE! | X3: =U3*(I3*I3) -> 0 | Y3: =H3-X3 -> 59
F4: =DATEDIF(E4,D4,"M") -> 0 | G4: =YEARFRAC(D4,E4) -> 0 | J4: =I4*100 -> 0 | L4: =K4/J4 -> #DIV/0! | M4: =IF(H4>0,IF(I4>0,H4/I4^2,""),"") | N4: =MATCH(F4,[2]IMC!B:B,0) -> #N/A | O4: =MATCH(M4,INDIRECT("IMC!F" & N4 & ":R" &N4),1) -> #N/A | P4: =CONCATENATE(INDEX(IMC!$F$1:$R$5,5,$O4) & " e " & INDEX(IMC!$F$1:$R$5,5,$O4+1)) -> #N/A | R4: =MATCH(F4,[3]PC!A:A,0) -> #N/A | S4: =MATCH(K4,INDIRECT("PC!E" & R4 & ":L" &R4),1) -> #N/A | T4: =CONCATENATE(INDEX([3]PC!$E$1:$M$2,1,$S4) & " e " & INDEX([3]PC!$E$1:$M$2,1,$S4+1)) -> #N/A | W4: =CONCATENATE(INDEX([3]IMC!$F$1:$R$5,5,$V4) & " e " & INDEX([3]IMC!$F$1:$R$5,5,$V4+1)) -> #VALUE! | X4: =U4*(I4*I4) -> 0 | Y4: =H4-X4 -> 0
F5: =DATEDIF(E5,D5,"M") -> 0 | G5: =YEARFRAC(D5,E5) -> 0 | J5: =I5*100 -> 0 | L5: =K5/J5 -> #DIV/0! | M5: =IF(H5>0,IF(I5>0,H5/I5^2,""),"") | N5: =MATCH(F5,[2]IMC!B:B,0) -> #N/A | O5: =MATCH(M5,INDIRECT("IMC!F" & N5 & ":R" &N5),1) -> #N/A | P5: =CONCATENATE(INDEX(IMC!$F$1:$R$5,5,$O5) & " e " & INDEX(IMC!$F$1:$R$5,5,$O5+1)) -> #N/A | R5: =MATCH(F5,[3]PC!A:A,0) -> #N/A | S5: =MATCH(K5,INDIRECT("PC!E" & R5 & ":L" &R5),1) -> #N/A | T5: =CONCATENATE(INDEX([3]PC!$E$1:$M$2,1,$S5) & " e " & INDEX([3]PC!$E$1:$M$2,1,$S5+1)) -> #N/A | W5: =CONCATENATE(INDEX([3]IMC!$F$1:$R$5,5,$V5) & " e " & INDEX([3]IMC!$F$1:$R$5,5,$V5+1)) -> #VALUE! | X5: =U5*(I5*I5) -> 0 | Y5: =H5-X5 -> 0
F6: =DATEDIF(E6,D6,"M") -> 0 | G6: =YEARFRAC(D6,E6) -> 0 | J6: =I6*100 -> 0 | L6: =K6/J6 -> #DIV/0! | M6: =IF(H6>0,IF(I6>0,H6/I6^2,""),"") | N6: =MATCH(F6,[2]IMC!B:B,0) -> #N/A | O6: =MATCH(M6,INDIRECT("IMC!F" & N6 & ":R" &N6),1) -> #N/A | P6: =CONCATENATE(INDEX(IMC!$F$1:$R$5,5,$O6) & " e " & INDEX(IMC!$F$1:$R$5,5,$O6+1)) -> #N/A | R6: =MATCH(F6,[3]PC!A:A,0) -> #N/A | S6: =MATCH(K6,INDIRECT("PC!E" & R6 & ":L" &R6),1) -> #N/A | T6: =CONCATENATE(INDEX([3]PC!$E$1:$M$2,1,$S6) & " e " & INDEX([3]PC!$E$1:$M$2,1,$S6+1)) -> #N/A | W6: =CONCATENATE(INDEX([3]IMC!$F$1:$R$5,5,$V6) & " e " & INDEX([3]IMC!$F$1:$R$5,5,$V6+1)) -> #VALUE! | X6: =U6*(I6*I6) -> 0 | Y6: =H6-X6 -> 0
F7: =DATEDIF(E7,D7,"M") -> 0 | G7: =YEARFRAC(D7,E7) -> 0 | J7: =I7*100 -> 0 | L7: =K7/J7 -> #DIV/0! | M7: =IF(H7>0,IF(I7>0,H7/I7^2,""),"") | N7: =MATCH(F7,[2]IMC!B:B,0) -> #N/A | O7: =MATCH(M7,INDIRECT("IMC!F" & N7 & ":R" &N7),1) -> #N/A | P7: =CONCATENATE(INDEX(IMC!$F$1:$R$5,5,$O7) & " e " & INDEX(IMC!$F$1:$R$5,5,$O7+1)) -> #N/A | R7: =MATCH(F7,[3]PC!A:A,0) -> #N/A | S7: =MATCH(K7,INDIRECT("PC!E" & R7 & ":L" &R7),1) -> #N/A | T7: =CONCATENATE(INDEX([3]PC!$E$1:$M$2,1,$S7) & " e " & INDEX([3]PC!$E$1:$M$2,1,$S7+1)) -> #N/A | W7: =CONCATENATE(INDEX([3]IMC!$F$1:$R$5,5,$V7) & " e " & INDEX([3]IMC!$F$1:$R$5,5,$V7+1)) -> #VALUE! | X7: =U7*(I7*I7) -> 0 | Y7: =H7-X7 -> 0
D8: 44570 | E8: 39714 | F8: =DATEDIF(E8,D8,"M") -> 159 | G8: =YEARFRAC(D8,E8) -> 13.294444 | H8: 69.1 | I8: 1.72 | J8: =I8*100 -> 172 | L8: =K8/J8 -> 0 | M8: =IF(H8>0,IF(I8>0,H8/I8^2,""),"") -> 23.35722 | N8: =MATCH(F8,[3]IMC!B:B,0) -> 141 | O8: =MATCH(M8,INDIRECT("IMC!F" & N8 & ":R" &N8),1) -> 9 | P8: =CONCATENATE(INDEX(IMC!$F$1:$R$5,5,$O8) & " e " & INDEX(IMC!$F$1:$R$5,5,$O8+1)) -> 85th e 95th | R8: =MATCH(F8,[3]PC!A:A,0) -> 47 | S8: =MATCH(K8,INDIRECT("PC!E" & R8 & ":L" &R8),1) -> #REF! | T8: =CONCATENATE(INDEX([3]PC!$E$1:$M$2,1,$S8) & " e " & INDEX([3]PC!$E$1:$M$2,1,$S8+1)) -> #REF! | W8: =CONCATENATE(INDEX([3]IMC!$F$1:$R$5,5,$V8) & " e " & INDEX([3]IMC!$F$1:$R$5,5,$V8+1)) -> #VALUE! | X8: =U8*(I8*I8) -> 0 | Y8: =H8-X8 -> 69.1
F9: =DATEDIF(E9,D9,"M") -> 0 | G9: =YEARFRAC(D9,E9) -> 0 | J9: =I9*100 -> 0 | L9: =K9/J9 -> #DIV/0! | M9: =IF(H9>0,IF(I9>0,H9/I9^2,""),"") | N9: =MATCH(F9,[3]IMC!B:B,0) -> #N/A | O9: =MATCH(M9,INDIRECT("IMC!F" & N9 & ":R" &N9),1) -> #N/A | P9: =CONCATENATE(INDEX(IMC!$F$1:$R$5,5,$O9) & " e " & INDEX(IMC!$F$1:$R$5,5,$O9+1)) -> #N/A | R9: =MATCH(F9,[3]PC!A:A,0) -> #N/A | S9: =MATCH(K9,INDIRECT("PC!E" & R9 & ":L" &R9),1) -> #N/A | T9: =CONCATENATE(INDEX([3]PC!$E$1:$M$2,1,$S9) & " e " & INDEX([3]PC!$E$1:$M$2,1,$S9+1)) -> #N/A | W9: =CONCATENATE(INDEX([3]IMC!$F$1:$R$5,5,$V9) & " e " & INDEX([3]IMC!$F$1:$R$5,5,$V9+1)) -> #VALUE! | X9: =U9*(I9*I9) -> 0 | Y9: =H9-X9 -> 0
F10: =DATEDIF(E10,D10,"M") -> 0 | G10: =YEARFRAC(D10,E10) -> 0 | J10: =I10*100 -> 0 | L10: =K10/J10 -> #DIV/0! | M10: =IF(H10>0,IF(I10>0,H10/I10^2,""),"") | N10: =MATCH(F10,[3]IMC!B:B,0) -> #N/A | O10: =MATCH(M10,INDIRECT("IMC!F" & N10 & ":R" &N10),1) -> #N/A | P10: =CONCATENATE(INDEX(IMC!$F$1:$R$5,5,$O10) & " e " & INDEX(IMC!$F$1:$R$5,5,$O10+1)) -> #N/A | R10: =MATCH(F10,[3]PC!A:A,0) -> #N/A | S10: =MATCH(K10,INDIRECT("PC!E" & R10 & ":L" &R10),1) -> #N/A | T10: =CONCATENATE(INDEX([3]PC!$E$1:$M$2,1,$S10) & " e " & INDEX([3]PC!$E$1:$M$2,1,$S10+1)) -> #N/A | W10: =CONCATENATE(INDEX([3]IMC!$F$1:$R$5,5,$V10) & " e " & INDEX([3]IMC!$F$1:$R$5,5,$V10+1)) -> #VALUE! | X10: =U10*(I10*I10) -> 0 | Y10: =H10-X10 -> 0
F11: =DATEDIF(E11,D11,"M") -> 0 | G11: =YEARFRAC(D11,E11) -> 0 | J11: =I11*100 -> 0 | L11: =K11/J11 -> #DIV/0! | M11: =IF(H11>0,IF(I11>0,H11/I11^2,""),"") | N11: =MATCH(F11,[3]IMC!B:B,0) -> #N/A | O11: =MATCH(M11,INDIRECT("IMC!F" & N11 & ":R" &N11),1) -> #N/A | P11: =CONCATENATE(INDEX(IMC!$F$1:$R$5,5,$O11) & " e " & INDEX(IMC!$F$1:$R$5,5,$O11+1)) -> #N/A | R11: =MATCH(F11,[3]PC!A:A,0) -> #N/A | S11: =MATCH(K11,INDIRECT("PC!E" & R11 & ":L" &R11),1) -> #N/A | T11: =CONCATENATE(INDEX([3]PC!$E$1:$M$2,1,$S11) & " e " & INDEX([3]PC!$E$1:$M$2,1,$S11+1)) -> #N/A | W11: =CONCATENATE(INDEX([3]IMC!$F$1:$R$5,5,$V11) & " e " & INDEX([3]IMC!$F$1:$R$5,5,$V11+1)) -> #VALUE! | X11: =U11*(I11*I11) -> 0 | Y11: =H11-X11 -> 0
F12: =DATEDIF(E12,D12,"M") -> 0 | G12: =YEARFRAC(D12,E12) -> 0 | J12: =I12*100 -> 0 | L12: =K12/J12 -> #DIV/0! | M12: =IF(H12>0,IF(I12>0,H12/I12^2,""),"") | N12: =MATCH(F12,[3]IMC!B:B,0) -> #N/A | O12: =MATCH(M12,INDIRECT("IMC!F" & N12 & ":R" &N12),1) -> #N/A | P12: =CONCATENATE(INDEX(IMC!$F$1:$R$5,5,$O12) & " e " & INDEX(IMC!$F$1:$R$5,5,$O12+1)) -> #N/A | R12: =MATCH(F12,[3]PC!A:A,0) -> #N/A | S12: =MATCH(K12,INDIRECT("PC!E" & R12 & ":L" &R12),1) -> #N/A | T12: =CONCATENATE(INDEX([3]PC!$E$1:$M$2,1,$S12) & " e " & INDEX([3]PC!$E$1:$M$2,1,$S12+1)) -> #N/A | W12: =CONCATENATE(INDEX([3]IMC!$F$1:$R$5,5,$V12) & " e " & INDEX([3]IMC!$F$1:$R$5,5,$V12+1)) -> #VALUE! | X12: =U12*(I12*I12) -> 0 | Y12: =H12-X12 -> 0
F13: =DATEDIF(E13,D13,"M") -> 0 | G13: =YEARFRAC(D13,E13) -> 0 | J13: =I13*100 -> 0 | L13: =K13/J13 -> #DIV/0! | M13: =IF(H13>0,IF(I13>0,H13/I13^2,""),"") | N13: =MATCH(F13,[3]IMC!B:B,0) -> #N/A | O13: =MATCH(M13,INDIRECT("IMC!F" & N13 & ":R" &N13),1) -> #N/A | P13: =CONCATENATE(INDEX(IMC!$F$1:$R$5,5,$O13) & " e " & INDEX(IMC!$F$1:$R$5,5,$O13+1)) -> #N/A | R13: =MATCH(F13,[3]PC!A:A,0) -> #N/A | S13: =MATCH(K13,INDIRECT("PC!E" & R13 & ":L" &R13),1) -> #N/A | T13: =CONCATENATE(INDEX([3]PC!$E$1:$M$2,1,$S13) & " e " & INDEX([3]PC!$E$1:$M$2,1,$S13+1)) -> #N/A | W13: =CONCATENATE(INDEX([3]IMC!$F$1:$R$5,5,$V13) & " e " & INDEX([3]IMC!$F$1:$R$5,5,$V13+1)) -> #VALUE! | X13: =U13*(I13*I13) -> 0 | Y13: =H13-X13 -> 0
F14: =DATEDIF(E14,D14,"M") -> 0 | G14: =YEARFRAC(D14,E14) -> 0 | J14: =I14*100 -> 0 | L14: =K14/J14 -> #DIV/0! | M14: =IF(H14>0,IF(I14>0,H14/I14^2,""),"") | N14: =MATCH(F14,[3]IMC!B:B,0) -> #N/A | O14: =MATCH(M14,INDIRECT("IMC!F" & N14 & ":R" &N14),1) -> #N/A | P14: =CONCATENATE(INDEX(IMC!$F$1:$R$5,5,$O14) & " e " & INDEX(IMC!$F$1:$R$5,5,$O14+1)) -> #N/A | R14: =MATCH(F14,[3]PC!A:A,0) -> #N/A | S14: =MATCH(K14,INDIRECT("PC!E" & R14 & ":L" &R14),1) -> #N/A | T14: =CONCATENATE(INDEX([3]PC!$E$1:$M$2,1,$S14) & " e " & INDEX([3]PC!$E$1:$M$2,1,$S14+1)) -> #N/A | W14: =CONCATENATE(INDEX([3]IMC!$F$1:$R$5,5,$V14) & " e " & INDEX([3]IMC!$F$1:$R$5,5,$V14+1)) -> #VALUE! | X14: =U14*(I14*I14) -> 0 | Y14: =H14-X14 -> 0
F15: =DATEDIF(E15,D15,"M") -> 0 | G15: =YEARFRAC(D15,E15) -> 0 | J15: =I15*100 -> 0 | L15: =K15/J15 -> #DIV/0! | M15: =IF(H15>0,IF(I15>0,H15/I15^2,""),"") | N15: =MATCH(F15,[3]IMC!B:B,0) -> #N/A | O15: =MATCH(M15,INDIRECT("IMC!F" & N15 & ":R" &N15),1) -> #N/A | P15: =CONCATENATE(INDEX(IMC!$F$1:$R$5,5,$O15) & " e " & INDEX(IMC!$F$1:$R$5,5,$O15+1)) -> #N/A | R15: =MATCH(F15,[3]PC!A:A,0) -> #N/A | S15: =MATCH(K15,INDIRECT("PC!E" & R15 & ":L" &R15),1) -> #N/A | T15: =CONCATENATE(INDEX([3]PC!$E$1:$M$2,1,$S15) & " e " & INDEX([3]PC!$E$1:$M$2,1,$S15+1)) -> #N/A | W15: =CONCATENATE(INDEX([3]IMC!$F$1:$R$5,5,$V15) & " e " & INDEX([3]IMC!$F$1:$R$5,5,$V15+1)) -> #VALUE! | X15: =U15*(I15*I15) -> 0 | Y15: =H15-X15 -> 0
F16: =DATEDIF(E16,D16,"M") -> 0 | G16: =YEARFRAC(D16,E16) -> 0 | J16: =I16*100 -> 0 | L16: =K16/J16 -> #DIV/0! | M16: =IF(H16>0,IF(I16>0,H16/I16^2,""),"") | N16: =MATCH(F16,[3]IMC!B:B,0) -> #N/A | O16: =MATCH(M16,INDIRECT("IMC!F" & N16 & ":R" &N16),1) -> #N/A | P16: =CONCATENATE(INDEX(IMC!$F$1:$R$5,5,$O16) & " e " & INDEX(IMC!$F$1:$R$5,5,$O16+1)) -> #N/A | R16: =MATCH(F16,[3]PC!A:A,0) -> #N/A | S16: =MATCH(K16,INDIRECT("PC!E" & R16 & ":L" &R16),1) -> #N/A | T16: =CONCATENATE(INDEX([3]PC!$E$1:$M$2,1,$S16) & " e " & INDEX([3]PC!$E$1:$M$2,1,$S16+1)) -> #N/A | W16: =CONCATENATE(INDEX([3]IMC!$F$1:$R$5,5,$V16) & " e " & INDEX([3]IMC!$F$1:$R$5,5,$V16+1)) -> #VALUE! | X16: =U16*(I16*I16) -> 0 | Y16: =H16-X16 -> 0
F17: =DATEDIF(E17,D17,"M") -> 0 | G17: =YEARFRAC(D17,E17) -> 0 | J17: =I17*100 -> 0 | L17: =K17/J17 -> #DIV/0! | M17: =IF(H17>0,IF(I17>0,H17/I17^2,""),"") | N17: =MATCH(F17,[3]IMC!B:B,0) -> #N/A | O17: =MATCH(M17,INDIRECT("IMC!F" & N17 & ":R" &N17),1) -> #N/A | P17: =CONCATENATE(INDEX(IMC!$F$1:$R$5,5,$O17) & " e " & INDEX(IMC!$F$1:$R$5,5,$O17+1)) -> #N/A | R17: =MATCH(F17,[3]PC!A:A,0) -> #N/A | S17: =MATCH(K17,INDIRECT("PC!E" & R17 & ":L" &R17),1) -> #N/A | T17: =CONCATENATE(INDEX([3]PC!$E$1:$M$2,1,$S17) & " e " & INDEX([3]PC!$E$1:$M$2,1,$S17+1)) -> #N/A | W17: =CONCATENATE(INDEX([3]IMC!$F$1:$R$5,5,$V17) & " e " & INDEX([3]IMC!$F$1:$R$5,5,$V17+1)) -> #VALUE! | X17: =U17*(I17*I17) -> 0 | Y17: =H17-X17 -> 0
